Workbook

Sheet 真值表
A1: # | B1: 指令 | C1: Funct7 (十进制) | D1: Funct3 (十进制) | E1: OpCode (十六进制) | F1: F30 | G1: F25 | H1: F14 | I1: F13 | J1: F12 | K1: OP6 | L1: OP5 | M1: OP4 | N1: OP3 | O1: OP2 | P1: ALU_OP | Q1: S3 | R1: S2 | S1: S1 | T1: S0 | U1: MemtoReg | V1: MemWrite | W1: ALU_Src | X1: RegWrite | Y1: ecall | Z1: S_Type | AA1: BEQ | AB1: BNE | AC1: JAL | AD1: JALR | AE1: LHU | AF1: BLT | AH1: r1_used | AI1: r2_used | AJ1: XXX | AK1: XXX | AL1: XXX | AM1: XXX | AN1: 可增加列，自定义控制信号
A2: 1 | B2: add | C2: 0 | D2: 0 | E2: C | F2: =IF(ISNUMBER($C2),IF(MOD($C2,64)/32>=1,1,0),"") -> 0 | G2: =IF(ISNUMBER($C2),IF(MOD($C2,2)>=1,1,0),"") -> 0 | H2: =IF(ISNUMBER($D2),IF(MOD($D2,8)/4>=1,1,0),"") -> 0 | I2: =IF(ISNUMBER($D2),IF(MOD($D2,4)/2>=1,1,0),"") -> 0 | J2: =IF(ISNUMBER($D2),IF(MOD($D2,2)>=1,1,0),"") -> 0 | K2: =IF(ISBLANK($E2),"",IF(MOD(HEX2DEC($E2),32)/16>=1,1,0)) -> 0 | L2: =IF(ISBLANK($E2),"",IF(MOD(HEX2DEC($E2),16)/8>=1,1,0)) -> 1 | M2: =IF(ISBLANK($E2),"",IF(MOD(HEX2DEC($E2),8)/4>=1,1,0)) -> 1 | N2: =IF(ISBLANK($E2),"",IF(MOD(HEX2DEC($E2),4)/2>=1,1,0)) -> 0 | O2: =IF(ISBLANK($E2),"",IF(MOD(HEX2DEC($E2),2)>=1,1,0)) -> 0 | P2: 5 | Q2: =IF(ISNUMBER($P2),IF(MOD($P2,16)/8>=1,1,0),"X") -> 0 | R2: =IF(ISNUMBER($P2),IF(MOD($P2,8)/4>=1,1,0),"X") -> 1 | S2: =IF(ISNUMBER($P2),IF(MOD($P2,4)/2>=1,1,0),"X") -> 0 | T2: =IF(ISNUMBER($P2),IF(MOD($P2,2)>=1,1,0),"X") -> 1 | X2: 1 | AH2: 1 | AI2: 1
A3: 2 | B3: sub | C3: 32 | D3: 0 | E3: C | F3: =IF(ISNUMBER($C3),IF(MOD($C3,64)/32>=1,1,0),"") -> 1 | G3: =IF(ISNUMBER($C3),IF(MOD($C3,2)>=1,1,0),"") -> 0 | H3: =IF(ISNUMBER($D3),IF(MOD($D3,8)/4>=1,1,0),"") -> 0 | I3: =IF(ISNUMBER($D3),IF(MOD($D3,4)/2>=1,1,0),"") -> 0 | J3: =IF(ISNUMBER($D3),IF(MOD($D3,2)>=1,1,0),"") -> 0 | K3: =IF(ISBLANK($E3),"",IF(MOD(HEX2DEC($E3),32)/16>=1,1,0)) -> 0 | L3: =IF(ISBLANK($E3),"",IF(MOD(HEX2DEC($E3),16)/8>=1,1,0)) -> 1 | M3: =IF(ISBLANK($E3),"",IF(MOD(HEX2DEC($E3),8)/4>=1,1,0)) -> 1 | N3: =IF(ISBLANK($E3),"",IF(MOD(HEX2DEC($E3),4)/2>=1,1,0)) -> 0 | O3: =IF(ISBLANK($E3),"",IF(MOD(HEX2DEC($E3),2)>=1,1,0)) -> 0 | P3: 6 | Q3: =IF(ISNUMBER($P3),IF(MOD($P3,16)/8>=1,1,0),"X") -> 0 | R3: =IF(ISNUMBER($P3),IF(MOD($P3,8)/4>=1,1,0),"X") -> 1 | S3: =IF(ISNUMBER($P3),IF(MOD($P3,4)/2>=1,1,0),"X") -> 1 | T3: =IF(ISNUMBER($P3),IF(MOD($P3,2)>=1,1,0),"X") -> 0 | X3: 1 | AH3: 1 | AI3: 1
A4: 3 | B4: and | C4: 0 | D4: 7 | E4: C | F4: =IF(ISNUMBER($C4),IF(MOD($C4,64)/32>=1,1,0),"") -> 0 | G4: =IF(ISNUMBER($C4),IF(MOD($C4,2)>=1,1,0),"") -> 0 | H4: =IF(ISNUMBER($D4),IF(MOD($D4,8)/4>=1,1,0),"") -> 1 | I4: =IF(ISNUMBER($D4),IF(MOD($D4,4)/2>=1,1,0),"") -> 1 | J4: =IF(ISNUMBER($D4),IF(MOD($D4,2)>=1,1,0),"") -> 1 | K4: =IF(ISBLANK($E4),"",IF(MOD(HEX2DEC($E4),32)/16>=1,1,0)) -> 0 | L4: =IF(ISBLANK($E4),"",IF(MOD(HEX2DEC($E4),16)/8>=1,1,0)) -> 1 | M4: =IF(ISBLANK($E4),"",IF(MOD(HEX2DEC($E4),8)/4>=1,1,0)) -> 1 | N4: =IF(ISBLANK($E4),"",IF(MOD(HEX2DEC($E4),4)/2>=1,1,0)) -> 0 | O4: =IF(ISBLANK($E4),"",IF(MOD(HEX2DEC($E4),2)>=1,1,0)) -> 0 | P4: 7 | Q4: =IF(ISNUMBER($P4),IF(MOD($P4,16)/8>=1,1,0),"X") -> 0 | R4: =IF(ISNUMBER($P4),IF(MOD($P4,8)/4>=1,1,0),"X") -> 1 | S4: =IF(ISNUMBER($P4),IF(MOD($P4,4)/2>=1,1,0),"X") -> 1 | T4: =IF(ISNUMBER($P4),IF(MOD($P4,2)>=1,1,0),"X") -> 1 | X4: 1 | AH4: 1 | AI4: 1
A5: 4 | B5: or | C5: 0 | D5: 6 | E5: C | F5: =IF(ISNUMBER($C5),IF(MOD($C5,64)/32>=1,1,0),"") -> 0 | G5: =IF(ISNUMBER($C5),IF(MOD($C5,2)>=1,1,0),"") -> 0 | H5: =IF(ISNUMBER($D5),IF(MOD($D5,8)/4>=1,1,0),"") -> 1 | I5: =IF(ISNUMBER($D5),IF(MOD($D5,4)/2>=1,1,0),"") -> 1 | J5: =IF(ISNUMBER($D5),IF(MOD($D5,2)>=1,1,0),"") -> 0 | K5: =IF(ISBLANK($E5),"",IF(MOD(HEX2DEC($E5),32)/16>=1,1,0)) -> 0 | L5: =IF(ISBLANK($E5),"",IF(MOD(HEX2DEC($E5),16)/8>=1,1,0)) -> 1 | M5: =IF(ISBLANK($E5),"",IF(MOD(HEX2DEC($E5),8)/4>=1,1,0)) -> 1 | N5: =IF(ISBLANK($E5),"",IF(MOD(HEX2DEC($E5),4)/2>=1,1,0)) -> 0 | O5: =IF(ISBLANK($E5),"",IF(MOD(HEX2DEC($E5),2)>=1,1,0)) -> 0 | P5: 8 | Q5: =IF(ISNUMBER($P5),IF(MOD($P5,16)/8>=1,1,0),"X") -> 1 | R5: =IF(ISNUMBER($P5),IF(MOD($P5,8)/4>=1,1,0),"X") -> 0 | S5: =IF(ISNUMBER($P5),IF(MOD($P5,4)/2>=1,1,0),"X") -> 0 | T5: =IF(ISNUMBER($P5),IF(MOD($P5,2)>=1,1,0),"X") -> 0 | X5: 1 | AH5: 1 | AI5: 1
A6: 5 | B6: slt | C6: 0 | D6: 2 | E6: C | F6: =IF(ISNUMBER($C6),IF(MOD($C6,64)/32>=1,1,0),"") -> 0 | G6: =IF(ISNUMBER($C6),IF(MOD($C6,2)>=1,1,0),"") -> 0 | H6: =IF(ISNUMBER($D6),IF(MOD($D6,8)/4>=1,1,0),"") -> 0 | I6: =IF(ISNUMBER($D6),IF(MOD($D6,4)/2>=1,1,0),"") -> 1 | J6: =IF(ISNUMBER($D6),IF(MOD($D6,2)>=1,1,0),"") -> 0 | K6: =IF(ISBLANK($E6),"",IF(MOD(HEX2DEC($E6),32)/16>=1,1,0)) -> 0 | L6: =IF(ISBLANK($E6),"",IF(MOD(HEX2DEC($E6),16)/8>=1,1,0)) -> 1 | M6: =IF(ISBLANK($E6),"",IF(MOD(HEX2DEC($E6),8)/4>=1,1,0)) -> 1 | N6: =IF(ISBLANK($E6),"",IF(MOD(HEX2DEC($E6),4)/2>=1,1,0)) -> 0 | O6: =IF(ISBLANK($E6),"",IF(MOD(HEX2DEC($E6),2)>=1,1,0)) -> 0 | P6: 11 | Q6: =IF(ISNUMBER($P6),IF(MOD($P6,16)/8>=1,1,0),"X") -> 1 | R6: =IF(ISNUMBER($P6),IF(MOD($P6,8)/4>=1,1,0),"X") -> 0 | S6: =IF(ISNUMBER($P6),IF(MOD($P6,4)/2>=1,1,0),"X") -> 1 | T6: =IF(ISNUMBER($P6),IF(MOD($P6,2)>=1,1,0),"X") -> 1 | X6: 1 | AH6: 1 | AI6: 1
A7: 6 | B7: sltu | C7: 0 | D7: 3 | E7: C | F7: =IF(ISNUMBER($C7),IF(MOD($C7,64)/32>=1,1,0),"") -> 0 | G7: =IF(ISNUMBER($C7),IF(MOD($C7,2)>=1,1,0),"") -> 0 | H7: =IF(ISNUMBER($D7),IF(MOD($D7,8)/4>=1,1,0),"") -> 0 | I7: =IF(ISNUMBER($D7),IF(MOD($D7,4)/2>=1,1,0),"") -> 1 | J7: =IF(ISNUMBER($D7),IF(MOD($D7,2)>=1,1,0),"") -> 1 | K7: =IF(ISBLANK($E7),"",IF(MOD(HEX2DEC($E7),32)/16>=1,1,0)) -> 0 | L7: =IF(ISBLANK($E7),"",IF(MOD(HEX2DEC($E7),16)/8>=1,1,0)) -> 1 | M7: =IF(ISBLANK($E7),"",IF(MOD(HEX2DEC($E7),8)/4>=1,1,0)) -> 1 | N7: =IF(ISBLANK($E7),"",IF(MOD(HEX2DEC($E7),4)/2>=1,1,0)) -> 0 | O7: =IF(ISBLANK($E7),"",IF(MOD(HEX2DEC($E7),2)>=1,1,0)) -> 0 | P7: 12 | Q7: =IF(ISNUMBER($P7),IF(MOD($P7,16)/8>=1,1,0),"X") -> 1 | R7: =IF(ISNUMBER($P7),IF(MOD($P7,8)/4>=1,1,0),"X") -> 1 | S7: =IF(ISNUMBER($P7),IF(MOD($P7,4)/2>=1,1,0),"X") -> 0 | T7: =IF(ISNUMBER($P7),IF(MOD($P7,2)>=1,1,0),"X") -> 0 | X7: 1 | AH7: 1 | AI7: 1
A8: 7 | B8: addi | D8: 0 | E8: 4 | F8: =IF(ISNUMBER($C8),IF(MOD($C8,64)/32>=1,1,0),"") | G8: =IF(ISNUMBER($C8),IF(MOD($C8,2)>=1,1,0),"") | H8: =IF(ISNUMBER($D8),IF(MOD($D8,8)/4>=1,1,0),"") -> 0 | I8: =IF(ISNUMBER($D8),IF(MOD($D8,4)/2>=1,1,0),"") -> 0 | J8: =IF(ISNUMBER($D8),IF(MOD($D8,2)>=1,1,0),"") -> 0 | K8: =IF(ISBLANK($E8),"",IF(MOD(HEX2DEC($E8),32)/16>=1,1,0)) -> 0 | L8: =IF(ISBLANK($E8),"",IF(MOD(HEX2DEC($E8),16)/8>=1,1,0)) -> 0 | M8: =IF(ISBLANK($E8),"",IF(MOD(HEX2DEC($E8),8)/4>=1,1,0)) -> 1 | N8: =IF(ISBLANK($E8),"",IF(MOD(HEX2DEC($E8),4)/2>=1,1,0)) -> 0 | O8: =IF(ISBLANK($E8),"",IF(MOD(HEX2DEC($E8),2)>=1,1,0)) -> 0 | P8: 5 | Q8: =IF(ISNUMBER($P8),IF(MOD($P8,16)/8>=1,1,0),"X") -> 0 | R8: =IF(ISNUMBER($P8),IF(MOD($P8,8)/4>=1,1,0),"X") -> 1 | S8: =IF(ISNUMBER($P8),IF(MOD($P8,4)/2>=1,1,0),"X") -> 0 | T8: =IF(ISNUMBER($P8),IF(MOD($P8,2)>=1,1,0),"X") -> 1 | W8: 1 | X8: 1 | AH8: 1
A9: 8 | B9: andi | D9: 7 | E9: 4 | F9: =IF(ISNUMBER($C9),IF(MOD($C9,64)/32>=1,1,0),"") | G9: =IF(ISNUMBER($C9),IF(MOD($C9,2)>=1,1,0),"") | H9: =IF(ISNUMBER($D9),IF(MOD($D9,8)/4>=1,1,0),"") -> 1 | I9: =IF(ISNUMBER($D9),IF(MOD($D9,4)/2>=1,1,0),"") -> 1 | J9: =IF(ISNUMBER($D9),IF(MOD($D9,2)>=1,1,0),"") -> 1 | K9: =IF(ISBLANK($E9),"",IF(MOD(HEX2DEC($E9),32)/16>=1,1,0)) -> 0 | L9: =IF(ISBLANK($E9),"",IF(MOD(HEX2DEC($E9),16)/8>=1,1,0)) -> 0 | M9: =IF(ISBLANK($E9),"",IF(MOD(HEX2DEC($E9),8)/4>=1,1,0)) -> 1 | N9: =IF(ISBLANK($E9),"",IF(MOD(HEX2DEC($E9),4)/2>=1,1,0)) -> 0 | O9: =IF(ISBLANK($E9),"",IF(MOD(HEX2DEC($E9),2)>=1,1,0)) -> 0 | P9: 7 | Q9: =IF(ISNUMBER($P9),IF(MOD($P9,16)/8>=1,1,0),"X") -> 0 | R9: =IF(ISNUMBER($P9),IF(MOD($P9,8)/4>=1,1,0),"X") -> 1 | S9: =IF(ISNUMBER($P9),IF(MOD($P9,4)/2>=1,1,0),"X") -> 1 | T9: =IF(ISNUMBER($P9),IF(MOD($P9,2)>=1,1,0),"X") -> 1 | W9: 1 | X9: 1 | AH9: 1
A10: 9 | B10: ori | D10: 6 | E10: 4 | F10: =IF(ISNUMBER($C10),IF(MOD($C10,64)/32>=1,1,0),"") | G10: =IF(ISNUMBER($C10),IF(MOD($C10,2)>=1,1,0),"") | H10: =IF(ISNUMBER($D10),IF(MOD($D10,8)/4>=1,1,0),"") -> 1 | I10: =IF(ISNUMBER($D10),IF(MOD($D10,4)/2>=1,1,0),"") -> 1 | J10: =IF(ISNUMBER($D10),IF(MOD($D10,2)>=1,1,0),"") -> 0 | K10: =IF(ISBLANK($E10),"",IF(MOD(HEX2DEC($E10),32)/16>=1,1,0)) -> 0 | L10: =IF(ISBLANK($E10),"",IF(MOD(HEX2DEC($E10),16)/8>=1,1,0)) -> 0 | M10: =IF(ISBLANK($E10),"",IF(MOD(HEX2DEC($E10),8)/4>=1,1,0)) -> 1 | N10: =IF(ISBLANK($E10),"",IF(MOD(HEX2DEC($E10),4)/2>=1,1,0)) -> 0 | O10: =IF(ISBLANK($E10),"",IF(MOD(HEX2DEC($E10),2)>=1,1,0)) -> 0 | P10: 8 | Q10: =IF(ISNUMBER($P10),IF(MOD($P10,16)/8>=1,1,0),"X") -> 1 | R10: =IF(ISNUMBER($P10),IF(MOD($P10,8)/4>=1,1,0),"X") -> 0 | S10: =IF(ISNUMBER($P10),IF(MOD($P10,4)/2>=1,1,0),"X") -> 0 | T10: =IF(ISNUMBER($P10),IF(MOD($P10,2)>=1,1,0),"X") -> 0 | W10: 1 | X10: 1 | AH10: 1
A11: 10 | B11: xori | D11: 4 | E11: 4 | F11: =IF(ISNUMBER($C11),IF(MOD($C11,64)/32>=1,1,0),"") | G11: =IF(ISNUMBER($C11),IF(MOD($C11,2)>=1,1,0),"") | H11: =IF(ISNUMBER($D11),IF(MOD($D11,8)/4>=1,1,0),"") -> 1 | I11: =IF(ISNUMBER($D11),IF(MOD($D11,4)/2>=1,1,0),"") -> 0 | J11: =IF(ISNUMBER($D11),IF(MOD($D11,2)>=1,1,0),"") -> 0 | K11: =IF(ISBLANK($E11),"",IF(MOD(HEX2DEC($E11),32)/16>=1,1,0)) -> 0 | L11: =IF(ISBLANK($E11),"",IF(MOD(HEX2DEC($E11),16)/8>=1,1,0)) -> 0 | M11: =IF(ISBLANK($E11),"",IF(MOD(HEX2DEC($E11),8)/4>=1,1,0)) -> 1 | N11: =IF(ISBLANK($E11),"",IF(MOD(HEX2DEC($E11),4)/2>=1,1,0)) -> 0 | O11: =IF(ISBLANK($E11),"",IF(MOD(HEX2DEC($E11),2)>=1,1,0)) -> 0 | P11: 9 | Q11: =IF(ISNUMBER($P11),IF(MOD($P11,16)/8>=1,1,0),"X") -> 1 | R11: =IF(ISNUMBER($P11),IF(MOD($P11,8)/4>=1,1,0),"X") -> 0 | S11: =IF(ISNUMBER($P11),IF(MOD($P11,4)/2>=1,1,0),"X") -> 0 | T11: =IF(ISNUMBER($P11),IF(MOD($P11,2)>=1,1,0),"X") -> 1 | W11: 1 | X11: 1 | AH11: 1
A12: 11 | B12: slti | D12: 2 | E12: 4 | F12: =IF(ISNUMBER($C12),IF(MOD($C12,64)/32>=1,1,0),"") | G12: =IF(ISNUMBER($C12),IF(MOD($C12,2)>=1,1,0),"") | H12: =IF(ISNUMBER($D12),IF(MOD($D12,8)/4>=1,1,0),"") -> 0 | I12: =IF(ISNUMBER($D12),IF(MOD($D12,4)/2>=1,1,0),"") -> 1 | J12: =IF(ISNUMBER($D12),IF(MOD($D12,2)>=1,1,0),"") -> 0 | K12: =IF(ISBLANK($E12),"",IF(MOD(HEX2DEC($E12),32)/16>=1,1,0)) -> 0 | L12: =IF(ISBLANK($E12),"",IF(MOD(HEX2DEC($E12),16)/8>=1,1,0)) -> 0 | M12: =IF(ISBLANK($E12),"",IF(MOD(HEX2DEC($E12),8)/4>=1,1,0)) -> 1 | N12: =IF(ISBLANK($E12),"",IF(MOD(HEX2DEC($E12),4)/2>=1,1,0)) -> 0 | O12: =IF(ISBLANK($E12),"",IF(MOD(HEX2DEC($E12),2)>=1,1,0)) -> 0 | P12: 11 | Q12: =IF(ISNUMBER($P12),IF(MOD($P12,16)/8>=1,1,0),"X") -> 1 | R12: =IF(ISNUMBER($P12),IF(MOD($P12,8)/4>=1,1,0),"X") -> 0 | S12: =IF(ISNUMBER($P12),IF(MOD($P12,4)/2>=1,1,0),"X") -> 1 | T12: =IF(ISNUMBER($P12),IF(MOD($P12,2)>=1,1,0),"X") -> 1 | W12: 1 | X12: 1 | AH12: 1
A13: 12 | B13: slli | C13: 0 | D13: 1 | E13: 4 | F13: =IF(ISNUMBER($C13),IF(MOD($C13,64)/32>=1,1,0),"") -> 0 | G13: =IF(ISNUMBER($C13),IF(MOD($C13,2)>=1,1,0),"") -> 0 | H13: =IF(ISNUMBER($D13),IF(MOD($D13,8)/4>=1,1,0),"") -> 0 | I13: =IF(ISNUMBER($D13),IF(MOD($D13,4)/2>=1,1,0),"") -> 0 | J13: =IF(ISNUMBER($D13),IF(MOD($D13,2)>=1,1,0),"") -> 1 | K13: =IF(ISBLANK($E13),"",IF(MOD(HEX2DEC($E13),32)/16>=1,1,0)) -> 0 | L13: =IF(ISBLANK($E13),"",IF(MOD(HEX2DEC($E13),16)/8>=1,1,0)) -> 0 | M13: =IF(ISBLANK($E13),"",IF(MOD(HEX2DEC($E13),8)/4>=1,1,0)) -> 1 | N13: =IF(ISBLANK($E13),"",IF(MOD(HEX2DEC($E13),4)/2>=1,1,0)) -> 0 | O13: =IF(ISBLANK($E13),"",IF(MOD(HEX2DEC($E13),2)>=1,1,0)) -> 0 | P13: 0 | Q13: =IF(ISNUMBER($P13),IF(MOD($P13,16)/8>=1,1,0),"X") -> 0 | R13: =IF(ISNUMBER($P13),IF(MOD($P13,8)/4>=1,1,0),"X") -> 0 | S13: =IF(ISNUMBER($P13),IF(MOD($P13,4)/2>=1,1,0),"X") -> 0 | T13: =IF(ISNUMBER($P13),IF(MOD($P13,2)>=1,1,0),"X") -> 0 | W13: 1 | X13: 1 | AH13: 1
A14: 13 | B14: srli | C14: 0 | D14: 5 | E14: 4 | F14: =IF(ISNUMBER($C14),IF(MOD($C14,64)/32>=1,1,0),"") -> 0 | G14: =IF(ISNUMBER($C14),IF(MOD($C14,2)>=1,1,0),"") -> 0 | H14: =IF(ISNUMBER($D14),IF(MOD($D14,8)/4>=1,1,0),"") -> 1 | I14: =IF(ISNUMBER($D14),IF(MOD($D14,4)/2>=1,1,0),"") -> 0 | J14: =IF(ISNUMBER($D14),IF(MOD($D14,2)>=1,1,0),"") -> 1 | K14: =IF(ISBLANK($E14),"",IF(MOD(HEX2DEC($E14),32)/16>=1,1,0)) -> 0 | L14: =IF(ISBLANK($E14),"",IF(MOD(HEX2DEC($E14),16)/8>=1,1,0)) -> 0 | M14: =IF(ISBLANK($E14),"",IF(MOD(HEX2DEC($E14),8)/4>=1,1,0)) -> 1 | N14: =IF(ISBLANK($E14),"",IF(MOD(HEX2DEC($E14),4)/2>=1,1,0)) -> 0 | O14: =IF(ISBLANK($E14),"",IF(MOD(HEX2DEC($E14),2)>=1,1,0)) -> 0 | P14: 2 | Q14: =IF(ISNUMBER($P14),IF(MOD($P14,16)/8>=1,1,0),"X") -> 0 | R14: =IF(ISNUMBER($P14),IF(MOD($P14,8)/4>=1,1,0),"X") -> 0 | S14: =IF(ISNUMBER($P14),IF(MOD($P14,4)/2>=1,1,0),"X") -> 1 | T14: =IF(ISNUMBER($P14),IF(MOD($P14,2)>=1,1,0),"X") -> 0 | W14: 1 | X14: 1 | AH14: 1
A15: 14 | B15: srai | C15: 32 | D15: 5 | E15: 4 | F15: =IF(ISNUMBER($C15),IF(MOD($C15,64)/32>=1,1,0),"") -> 1 | G15: =IF(ISNUMBER($C15),IF(MOD($C15,2)>=1,1,0),"") -> 0 | H15: =IF(ISNUMBER($D15),IF(MOD($D15,8)/4>=1,1,0),"") -> 1 | I15: =IF(ISNUMBER($D15),IF(MOD($D15,4)/2>=1,1,0),"") -> 0 | J15: =IF(ISNUMBER($D15),IF(MOD($D15,2)>=1,1,0),"") -> 1 | K15: =IF(ISBLANK($E15),"",IF(MOD(HEX2DEC($E15),32)/16>=1,1,0)) -> 0 | L15: =IF(ISBLANK($E15),"",IF(MOD(HEX2DEC($E15),16)/8>=1,1,0)) -> 0 | M15: =IF(ISBLANK($E15),"",IF(MOD(HEX2DEC($E15),8)/4>=1,1,0)) -> 1 | N15: =IF(ISBLANK($E15),"",IF(MOD(HEX2DEC($E15),4)/2>=1,1,0)) -> 0 | O15: =IF(ISBLANK($E15),"",IF(MOD(HEX2DEC($E15),2)>=1,1,0)) -> 0 | P15: 1 | Q15: =IF(ISNUMBER($P15),IF(MOD($P15,16)/8>=1,1,0),"X") -> 0 | R15: =IF(ISNUMBER($P15),IF(MOD($P15,8)/4>=1,1,0),"X") -> 0 | S15: =IF(ISNUMBER($P15),IF(MOD($P15,4)/2>=1,1,0),"X") -> 0 | T15: =IF(ISNUMBER($P15),IF(MOD($P15,2)>=1,1,0),"X") -> 1 | W15: 1 | X15: 1 | AH15: 1
A16: 15 | B16: lw | D16: 2 | E16: 0 | F16: =IF(ISNUMBER($C16),IF(MOD($C16,64)/32>=1,1,0),"") | G16: =IF(ISNUMBER($C16),IF(MOD($C16,2)>=1,1,0),"") | H16: =IF(ISNUMBER($D16),IF(MOD($D16,8)/4>=1,1,0),"") -> 0 | I16: =IF(ISNUMBER($D16),IF(MOD($D16,4)/2>=1,1,0),"") -> 1 | J16: =IF(ISNUMBER($D16),IF(MOD($D16,2)>=1,1,0),"") -> 0 | K16: =IF(ISBLANK($E16),"",IF(MOD(HEX2DEC($E16),32)/16>=1,1,0)) -> 0 | L16: =IF(ISBLANK($E16),"",IF(MOD(HEX2DEC($E16),16)/8>=1,1,0)) -> 0 | M16: =IF(ISBLANK($E16),"",IF(MOD(HEX2DEC($E16),8)/4>=1,1,0)) -> 0 | N16: =IF(ISBLANK($E16),"",IF(MOD(HEX2DEC($E16),4)/2>=1,1,0)) -> 0 | O16: =IF(ISBLANK($E16),"",IF(MOD(HEX2DEC($E16),2)>=1,1,0)) -> 0 | P16: 5 | Q16: =IF(ISNUMBER($P16),IF(MOD($P16,16)/8>=1,1,0),"X") -> 0 | R16: =IF(ISNUMBER($P16),IF(MOD($P16,8)/4>=1,1,0),"X") -> 1 | S16: =IF(ISNUMBER($P16),IF(MOD($P16,4)/2>=1,1,0),"X") -> 0 | T16: =IF(ISNUMBER($P16),IF(MOD($P16,2)>=1,1,0),"X") -> 1 | U16: 1 | W16: 1 | X16: 1 | AH16: 1
A17: 16 | B17: sw | D17: 2 | E17: 8 | F17: =IF(ISNUMBER($C17),IF(MOD($C17,64)/32>=1,1,0),"") | G17: =IF(ISNUMBER($C17),IF(MOD($C17,2)>=1,1,0),"") | H17: =IF(ISNUMBER($D17),IF(MOD($D17,8)/4>=1,1,0),"") -> 0 | I17: =IF(ISNUMBER($D17),IF(MOD($D17,4)/2>=1,1,0),"") -> 1 | J17: =IF(ISNUMBER($D17),IF(MOD($D17,2)>=1,1,0),"") -> 0 | K17: =IF(ISBLANK($E17),"",IF(MOD(HEX2DEC($E17),32)/16>=1,1,0)) -> 0 | L17: =IF(ISBLANK($E17),"",IF(MOD(HEX2DEC($E17),16)/8>=1,1,0)) -> 1 | M17: =IF(ISBLANK($E17),"",IF(MOD(HEX2DEC($E17),8)/4>=1,1,0)) -> 0 | N17: =IF(ISBLANK($E17),"",IF(MOD(HEX2DEC($E17),4)/2>=1,1,0)) -> 0 | O17: =IF(ISBLANK($E17),"",IF(MOD(HEX2DEC($E17),2)>=1,1,0)) -> 0 | P17: 5 | Q17: =IF(ISNUMBER($P17),IF(MOD($P17,16)/8>=1,1,0),"X") -> 0 | R17: =IF(ISNUMBER($P17),IF(MOD($P17,8)/4>=1,1,0),"X") -> 1 | S17: =IF(ISNUMBER($P17),IF(MOD($P17,4)/2>=1,1,0),"X") -> 0 | T17: =IF(ISNUMBER($P17),IF(MOD($P17,2)>=1,1,0),"X") -> 1 | V17: 1 | W17: 1 | Z17: 1 | AH17: 1 | AI17: 1
A18: 17 | B18: ecall | C18: 0 | D18: 0 | E18: 1C | F18: =IF(ISNUMBER($C18),IF(MOD($C18,64)/32>=1,1,0),"") -> 0 | G18: =IF(ISNUMBER($C18),IF(MOD($C18,2)>=1,1,0),"") -> 0 | H18: =IF(ISNUMBER($D18),IF(MOD($D18,8)/4>=1,1,0),"") -> 0 | I18: =IF(ISNUMBER($D18),IF(MOD($D18,4)/2>=1,1,0),"") -> 0 | J18: =IF(ISNUMBER($D18),IF(MOD($D18,2)>=1,1,0),"") -> 0 | K18: =IF(ISBLANK($E18),"",IF(MOD(HEX2DEC($E18),32)/16>=1,1,0)) -> 1 | L18: =IF(ISBLANK($E18),"",IF(MOD(HEX2DEC($E18),16)/8>=1,1,0)) -> 1 | M18: =IF(ISBLANK($E18),"",IF(MOD(HEX2DEC($E18),8)/4>=1,1,0)) -> 1 | N18: =IF(ISBLANK($E18),"",IF(MOD(HEX2DEC($E18),4)/2>=1,1,0)) -> 0 | O18: =IF(ISBLANK($E18),"",IF(MOD(HEX2DEC($E18),2)>=1,1,0)) -> 0 | Q18: =IF(ISNUMBER($P18),IF(MOD($P18,16)/8>=1,1,0),"X") -> X | R18: =IF(ISNUMBER($P18),IF(MOD($P18,8)/4>=1,1,0),"X") -> X | S18: =IF(ISNUMBER($P18),IF(MOD($P18,4)/2>=1,1,0),"X") -> X | T18: =IF(ISNUMBER($P18),IF(MOD($P18,2)>=1,1,0),"X") -> X | Y18: 1
A19: 18 | B19: beq | D19: 0 | E19: 18 | F19: =IF(ISNUMBER($C19),IF(MOD($C19,64)/32>=1,1,0),"") | G19: =IF(ISNUMBER($C19),IF(MOD($C19,2)>=1,1,0),"") | H19: =IF(ISNUMBER($D19),IF(MOD($D19,8)/4>=1,1,0),"") -> 0 | I19: =IF(ISNUMBER($D19),IF(MOD($D19,4)/2>=1,1,0),"") -> 0 | J19: =IF(ISNUMBER($D19),IF(MOD($D19,2)>=1,1,0),"") -> 0 | K19: =IF(ISBLANK($E19),"",IF(MOD(HEX2DEC($E19),32)/16>=1,1,0)) -> 1 | L19: =IF(ISBLANK($E19),"",IF(MOD(HEX2DEC($E19),16)/8>=1,1,0)) -> 1 | M19: =IF(ISBLANK($E19),"",IF(MOD(HEX2DEC($E19),8)/4>=1,1,0)) -> 0 | N19: =IF(ISBLANK($E19),"",IF(MOD(HEX2DEC($E19),4)/2>=1,1,0)) -> 0 | O19: =IF(ISBLANK($E19),"",IF(MOD(HEX2DEC($E19),2)>=1,1,0)) -> 0 | P19: 6 | Q19: =IF(ISNUMBER($P19),IF(MOD($P19,16)/8>=1,1,0),"X") -> 0 | R19: =IF(ISNUMBER($P19),IF(MOD($P19,8)/4>=1,1,0),"X") -> 1 | S19: =IF(ISNUMBER($P19),IF(MOD($P19,4)/2>=1,1,0),"X") -> 1 | T19: =IF(ISNUMBER($P19),IF(MOD($P19,2)>=1,1,0),"X") -> 0 | AA19: 1 | AH19: 1 | AI19: 1
A20: 19 | B20: bne | D20: 1 | E20: 18 | F20: =IF(ISNUMBER($C20),IF(MOD($C20,64)/32>=1,1,0),"") | G20: =IF(ISNUMBER($C20),IF(MOD($C20,2)>=1,1,0),"") | H20: =IF(ISNUMBER($D20),IF(MOD($D20,8)/4>=1,1,0),"") -> 0 | I20: =IF(ISNUMBER($D20),IF(MOD($D20,4)/2>=1,1,0),"") -> 0 | J20: =IF(ISNUMBER($D20),IF(MOD($D20,2)>=1,1,0),"") -> 1 | K20: =IF(ISBLANK($E20),"",IF(MOD(HEX2DEC($E20),32)/16>=1,1,0)) -> 1 | L20: =IF(ISBLANK($E20),"",IF(MOD(HEX2DEC($E20),16)/8>=1,1,0)) -> 1 | M20: =IF(ISBLANK($E20),"",IF(MOD(HEX2DEC($E20),8)/4>=1,1,0)) -> 0 | N20: =IF(ISBLANK($E20),"",IF(MOD(HEX2DEC($E20),4)/2>=1,1,0)) -> 0 | O20: =IF(ISBLANK($E20),"",IF(MOD(HEX2DEC($E20),2)>=1,1,0)) -> 0 | P20: 6 | Q20: =IF(ISNUMBER($P20),IF(MOD($P20,16)/8>=1,1,0),"X") -> 0 | R20: =IF(ISNUMBER($P20),IF(MOD($P20,8)/4>=1,1,0),"X") -> 1 | S20: =IF(ISNUMBER($P20),IF(MOD($P20,4)/2>=1,1,0),"X") -> 1 | T20: =IF(ISNUMBER($P20),IF(MOD($P20,2)>=1,1,0),"X") -> 0 | AB20: 1 | AH20: 1 | AI20: 1
A21: 20 | B21: jal | E21: 1B | F21: =IF(ISNUMBER($C21),IF(MOD($C21,64)/32>=1,1,0),"") | G21: =IF(ISNUMBER($C21),IF(MOD($C21,2)>=1,1,0),"") | H21: =IF(ISNUMBER($D21),IF(MOD($D21,8)/4>=1,1,0),"") | I21: =IF(ISNUMBER($D21),IF(MOD($D21,4)/2>=1,1,0),"") | J21: =IF(ISNUMBER($D21),IF(MOD($D21,2)>=1,1,0),"") | K21: =IF(ISBLANK($E21),"",IF(MOD(HEX2DEC($E21),32)/16>=1,1,0)) -> 1 | L21: =IF(ISBLANK($E21),"",IF(MOD(HEX2DEC($E21),16)/8>=1,1,0)) -> 1 | M21: =IF(ISBLANK($E21),"",IF(MOD(HEX2DEC($E21),8)/4>=1,1,0)) -> 0 | N21: =IF(ISBLANK($E21),"",IF(MOD(HEX2DEC($E21),4)/2>=1,1,0)) -> 1 | O21: =IF(ISBLANK($E21),"",IF(MOD(HEX2DEC($E21),2)>=1,1,0)) -> 1 | Q21: =IF(ISNUMBER($P21),IF(MOD($P21,16)/8>=1,1,0),"X") -> X | R21: =IF(ISNUMBER($P21),IF(MOD($P21,8)/4>=1,1,0),"X") -> X | S21: =IF(ISNUMBER($P21),IF(MOD($P21,4)/2>=1,1,0),"X") -> X | T21: =IF(ISNUMBER($P21),IF(MOD($P21,2)>=1,1,0),"X") -> X | X21: 1 | AC21: 1
A22: 21 | B22: jalr | D22: 0 | E22: 19 | F22: =IF(ISNUMBER($C22),IF(MOD($C22,64)/32>=1,1,0),"") | G22: =IF(ISNUMBER($C22),IF(MOD($C22,2)>=1,1,0),"") | H22: =IF(ISNUMBER($D22),IF(MOD($D22,8)/4>=1,1,0),"") -> 0 | I22: =IF(ISNUMBER($D22),IF(MOD($D22,4)/2>=1,1,0),"") -> 0 | J22: =IF(ISNUMBER($D22),IF(MOD($D22,2)>=1,1,0),"") -> 0 | K22: =IF(ISBLANK($E22),"",IF(MOD(HEX2DEC($E22),32)/16>=1,1,0)) -> 1 | L22: =IF(ISBLANK($E22),"",IF(MOD(HEX2DEC($E22),16)/8>=1,1,0)) -> 1 | M22: =IF(ISBLANK($E22),"",IF(MOD(HEX2DEC($E22),8)/4>=1,1,0)) -> 0 | N22: =IF(ISBLANK($E22),"",IF(MOD(HEX2DEC($E22),4)/2>=1,1,0)) -> 0 | O22: =IF(ISBLANK($E22),"",IF(MOD(HEX2DEC($E22),2)>=1,1,0)) -> 1 | P22: 6 | Q22: =IF(ISNUMBER($P22),IF(MOD($P22,16)/8>=1,1,0),"X") -> 0 | R22: =IF(ISNUMBER($P22),IF(MOD($P22,8)/4>=1,1,0),"X") -> 1 | S22: =IF(ISNUMBER($P22),IF(MOD($P22,4)/2>=1,1,0),"X") -> 1 | T22: =IF(ISNUMBER($P22),IF(MOD($P22,2)>=1,1,0),"X") -> 0 | W22: 1 | X22: 1 | AD22: 1 | AH22: 1
A23: 22 | B23: CSRRSI | D23: 6 | E23: 1C | F23: =IF(ISNUMBER($C23),IF(MOD($C23,64)/32>=1,1,0),"") | G23: =IF(ISNUMBER($C23),IF(MOD($C23,2)>=1,1,0),"") | H23: =IF(ISNUMBER($D23),IF(MOD($D23,8)/4>=1,1,0),"") -> 1 | I23: =IF(ISNUMBER($D23),IF(MOD($D23,4)/2>=1,1,0),"") -> 1 | J23: =IF(ISNUMBER($D23),IF(MOD($D23,2)>=1,1,0),"") -> 0 | K23: =IF(ISBLANK($E23),"",IF(MOD(HEX2DEC($E23),32)/16>=1,1,0)) -> 1 | L23: =IF(ISBLANK($E23),"",IF(MOD(HEX2DEC($E23),16)/8>=1,1,0)) -> 1 | M23: =IF(ISBLANK($E23),"",IF(MOD(HEX2DEC($E23),8)/4>=1,1,0)) -> 1 | N23: =IF(ISBLANK($E23),"",IF(MOD(HEX2DEC($E23),4)/2>=1,1,0)) -> 0 | O23: =IF(ISBLANK($E23),"",IF(MOD(HEX2DEC($E23),2)>=1,1,0)) -> 0 | P23: 8 | Q23: =IF(ISNUMBER($P23),IF(MOD($P23,16)/8>=1,1,0),"X") -> 1 | R23: =IF(ISNUMBER($P23),IF(MOD($P23,8)/4>=1,1,0),"X") -> 0 | S23: =IF(ISNUMBER($P23),IF(MOD($P23,4)/2>=1,1,0),"X") -> 0 | T23: =IF(ISNUMBER($P23),IF(MOD($P23,2)>=1,1,0),"X") -> 0
A24: 23 | B24: CSRRCI | D24: 7 | E24: 1C | F24: =IF(ISNUMBER($C24),IF(MOD($C24,64)/32>=1,1,0),"") | G24: =IF(ISNUMBER($C24),IF(MOD($C24,2)>=1,1,0),"") | H24: =IF(ISNUMBER($D24),IF(MOD($D24,8)/4>=1,1,0),"") -> 1 | I24: =IF(ISNUMBER($D24),IF(MOD($D24,4)/2>=1,1,0),"") -> 1 | J24: =IF(ISNUMBER($D24),IF(MOD($D24,2)>=1,1,0),"") -> 1 | K24: =IF(ISBLANK($E24),"",IF(MOD(HEX2DEC($E24),32)/16>=1,1,0)) -> 1 | L24: =IF(ISBLANK($E24),"",IF(MOD(HEX2DEC($E24),16)/8>=1,1,0)) -> 1 | M24: =IF(ISBLANK($E24),"",IF(MOD(HEX2DEC($E24),8)/4>=1,1,0)) -> 1 | N24: =IF(ISBLANK($E24),"",IF(MOD(HEX2DEC($E24),4)/2>=1,1,0)) -> 0 | O24: =IF(ISBLANK($E24),"",IF(MOD(HEX2DEC($E24),2)>=1,1,0)) -> 0 | P24: 7 | Q24: =IF(ISNUMBER($P24),IF(MOD($P24,16)/8>=1,1,0),"X") -> 0 | R24: =IF(ISNUMBER($P24),IF(MOD($P24,8)/4>=1,1,0),"X") -> 1 | S24: =IF(ISNUMBER($P24),IF(MOD($P24,4)/2>=1,1,0),"X") -> 1 | T24: =IF(ISNUMBER($P24),IF(MOD($P24,2)>=1,1,0),"X") -> 1
A25: 24 | B25: URET | C25: 2 | D25: 0 | E25: 1C | F25: =IF(ISNUMBER($C25),IF(MOD($C25,64)/32>=1,1,0),"") -> 0 | G25: =IF(ISNUMBER($C25),IF(MOD($C25,2)>=1,1,0),"") -> 0 | H25: =IF(ISNUMBER($D25),IF(MOD($D25,8)/4>=1,1,0),"") -> 0 | I25: =IF(ISNUMBER($D25),IF(MOD($D25,4)/2>=1,1,0),"") -> 0 | J25: =IF(ISNUMBER($D25),IF(MOD($D25,2)>=1,1,0),"") -> 0 | K25: =IF(ISBLANK($E25),"",IF(MOD(HEX2DEC($E25),32)/16>=1,1,0)) -> 1 | L25: =IF(ISBLANK($E25),"",IF(MOD(HEX2DEC($E25),16)/8>=1,1,0)) -> 1 | M25: =IF(ISBLANK($E25),"",IF(MOD(HEX2DEC($E25),8)/4>=1,1,0)) -> 1 | N25: =IF(ISBLANK($E25),"",IF(MOD(HEX2DEC($E25),4)/2>=1,1,0)) -> 0 | O25: =IF(ISBLANK($E25),"",IF(MOD(HEX2DEC($E25),2)>=1,1,0)) -> 0 | Q25: =IF(ISNUMBER($P25),IF(MOD($P25,16)/8>=1,1,0),"X") -> X | R25: =IF(ISNUMBER($P25),IF(MOD($P25,8)/4>=1,1,0),"X") -> X | S25: =IF(ISNUMBER($P25),IF(MOD($P25,4)/2>=1,1,0),"X") -> X | T25: =IF(ISNUMBER($P25),IF(MOD($P25,2)>=1,1,0),"X") -> X
A26: 25 | B26: sra | C26: 32 | D26: 5 | E26: C | F26: =IF(ISNUMBER($C26),IF(MOD($C26,64)/32>=1,1,0),"") -> 1 | G26: =IF(ISNUMBER($C26),IF(MOD($C26,2)>=1,1,0),"") -> 0 | H26: =IF(ISNUMBER($D26),IF(MOD($D26,8)/4>=1,1,0),"") -> 1 | I26: =IF(ISNUMBER($D26),IF(MOD($D26,4)/2>=1,1,0),"") -> 0 | J26: =IF(ISNUMBER($D26),IF(MOD($D26,2)>=1,1,0),"") -> 1 | K26: =IF(ISBLANK($E26),"",IF(MOD(HEX2DEC($E26),32)/16>=1,1,0)) -> 0 | L26: =IF(ISBLANK($E26),"",IF(MOD(HEX2DEC($E26),16)/8>=1,1,0)) -> 1 | M26: =IF(ISBLANK($E26),"",IF(MOD(HEX2DEC($E26),8)/4>=1,1,0)) -> 1 | N26: =IF(ISBLANK($E26),"",IF(MOD(HEX2DEC($E26),4)/2>=1,1,0)) -> 0 | O26: =IF(ISBLANK($E26),"",IF(MOD(HEX2DEC($E26),2)>=1,1,0)) -> 0 | P26: 1 | Q26: =IF(ISNUMBER($P26),IF(MOD($P26,16)/8>=1,1,0),"X") -> 0 | R26: =IF(ISNUMBER($P26),IF(MOD($P26,8)/4>=1,1,0),"X") -> 0 | S26: =IF(ISNUMBER($P26),IF(MOD($P26,4)/2>=1,1,0),"X") -> 0 | T26: =IF(ISNUMBER($P26),IF(MOD($P26,2)>=1,1,0),"X") -> 1 | X26: 1 | AH26: 1 | AI26: 1
A27: 26 | B27: sltiu | D27: 3 | E27: 4 | F27: =IF(ISNUMBER($C27),IF(MOD($C27,64)/32>=1,1,0),"") | G27: =IF(ISNUMBER($C27),IF(MOD($C27,2)>=1,1,0),"") | H27: =IF(ISNUMBER($D27),IF(MOD($D27,8)/4>=1,1,0),"") -> 0 | I27: =IF(ISNUMBER($D27),IF(MOD($D27,4)/2>=1,1,0),"") -> 1 | J27: =IF(ISNUMBER($D27),IF(MOD($D27,2)>=1,1,0),"") -> 1 | K27: =IF(ISBLANK($E27),"",IF(MOD(HEX2DEC($E27),32)/16>=1,1,0)) -> 0 | L27: =IF(ISBLANK($E27),"",IF(MOD(HEX2DEC($E27),16)/8>=1,1,0)) -> 0 | M27: =IF(ISBLANK($E27),"",IF(MOD(HEX2DEC($E27),8)/4>=1,1,0)) -> 1 | N27: =IF(ISBLANK($E27),"",IF(MOD(HEX2DEC($E27),4)/2>=1,1,0)) -> 0 | O27: =IF(ISBLANK($E27),"",IF(MOD(HEX2DEC($E27),2)>=1,1,0)) -> 0 | P27: 12 | Q27: =IF(ISNUMBER($P27),IF(MOD($P27,16)/8>=1,1,0),"X") -> 1 | R27: =IF(ISNUMBER($P27),IF(MOD($P27,8)/4>=1,1,0),"X") -> 1 | S27: =IF(ISNUMBER($P27),IF(MOD($P27,4)/2>=1,1,0),"X") -> 0 | T27: =IF(ISNUMBER($P27),IF(MOD($P27,2)>=1,1,0),"X") -> 0 | W27: 1 | X27: 1 | AH27: 1
A28: 27 | B28: lhu | D28: 5 | E28: 0 | F28: =IF(ISNUMBER($C28),IF(MOD($C28,64)/32>=1,1,0),"") | G28: =IF(ISNUMBER($C28),IF(MOD($C28,2)>=1,1,0),"") | H28: =IF(ISNUMBER($D28),IF(MOD($D28,8)/4>=1,1,0),"") -> 1 | I28: =IF(ISNUMBER($D28),IF(MOD($D28,4)/2>=1,1,0),"") -> 0 | J28: =IF(ISNUMBER($D28),IF(MOD($D28,2)>=1,1,0),"") -> 1 | K28: =IF(ISBLANK($E28),"",IF(MOD(HEX2DEC($E28),32)/16>=1,1,0)) -> 0 | L28: =IF(ISBLANK($E28),"",IF(MOD(HEX2DEC($E28),16)/8>=1,1,0)) -> 0 | M28: =IF(ISBLANK($E28),"",IF(MOD(HEX2DEC($E28),8)/4>=1,1,0)) -> 0 | N28: =IF(ISBLANK($E28),"",IF(MOD(HEX2DEC($E28),4)/2>=1,1,0)) -> 0 | O28: =IF(ISBLANK($E28),"",IF(MOD(HEX2DEC($E28),2)>=1,1,0)) -> 0 | P28: 5 | Q28: =IF(ISNUMBER($P28),IF(MOD($P28,16)/8>=1,1,0),"X") -> 0 | R28: =IF(ISNUMBER($P28),IF(MOD($P28,8)/4>=1,1,0),"X") -> 1 | S28: =IF(ISNUMBER($P28),IF(MOD($P28,4)/2>=1,1,0),"X") -> 0 | T28: =IF(ISNUMBER($P28),IF(MOD($P28,2)>=1,1,0),"X") -> 1 | U28: 1 | W28: 1 | X28: 1 | AE28: 1 | AH28: 1
A29: 28 | B29: blt | D29: 4 | E29: 18 | F29: =IF(ISNUMBER($C29),IF(MOD($C29,64)/32>=1,1,0),"") | G29: =IF(ISNUMBER($C29),IF(MOD($C29,2)>=1,1,0),"") | H29: =IF(ISNUMBER($D29),IF(MOD($D29,8)/4>=1,1,0),"") -> 1 | I29: =IF(ISNUMBER($D29),IF(MOD($D29,4)/2>=1,1,0),"") -> 0 | J29: =IF(ISNUMBER($D29),IF(MOD($D29,2)>=1,1,0),"") -> 0 | K29: =IF(ISBLANK($E29),"",IF(MOD(HEX2DEC($E29),32)/16>=1,1,0)) -> 1 | L29: =IF(ISBLANK($E29),"",IF(MOD(HEX2DEC($E29),16)/8>=1,1,0)) -> 1 | M29: =IF(ISBLANK($E29),"",IF(MOD(HEX2DEC($E29),8)/4>=1,1,0)) -> 0 | N29: =IF(ISBLANK($E29),"",IF(MOD(HEX2DEC($E29),4)/2>=1,1,0)) -> 0 | O29: =IF(ISBLANK($E29),"",IF(MOD(HEX2DEC($E29),2)>=1,1,0)) -> 0 | P29: 11 | Q29: =IF(ISNUMBER($P29),IF(MOD($P29,16)/8>=1,1,0),"X") -> 1 | R29: =IF(ISNUMBER($P29),IF(MOD($P29,8)/4>=1,1,0),"X") -> 0 | S29: =IF(ISNUMBER($P29),IF(MOD($P29,4)/2>=1,1,0),"X") -> 1 | T29: =IF(ISNUMBER($P29),IF(MOD($P29,2)>=1,1,0),"X") -> 1 | AF29: 1 | AH29: 1 | AI29: 1
A30: 29 | F30: =IF(ISNUMBER($C30),IF(MOD($C30,64)/32>=1,1,0),"") | G30: =IF(ISNUMBER($C30),IF(MOD($C30,2)>=1,1,0),"") | H30: =IF(ISNUMBER($D30),IF(MOD($D30,8)/4>=1,1,0),"") | I30: =IF(ISNUMBER($D30),IF(MOD($D30,4)/2>=1,1,0),"") | J30: =IF(ISNUMBER($D30),IF(MOD($D30,2)>=1,1,0),"") | K30: =IF(ISBLANK($E30),"",IF(MOD(HEX2DEC($E30),32)/16>=1,1,0)) | L30: =IF(ISBLANK($E30),"",IF(MOD(HEX2DEC($E30),16)/8>=1,1,0)) | M30: =IF(ISBLANK($E30),"",IF(MOD(HEX2DEC($E30),8)/4>=1,1,0)) | N30: =IF(ISBLANK($E30),"",IF(MOD(HEX2DEC($E30),4)/2>=1,1,0)) | O30: =IF(ISBLANK($E30),"",IF(MOD(HEX2DEC($E30),2)>=1,1,0)) | Q30: =IF(ISNUMBER($P30),IF(MOD($P30,16)/8>=1,1,0),"X") -> X | R30: =IF(ISNUMBER($P30),IF(MOD($P30,8)/4>=1,1,0),"X") -> X | S30: =IF(ISNUMBER($P30),IF(MOD($P30,4)/2>=1,1,0),"X") -> X | T30: =IF(ISNUMBER($P30),IF(MOD($P30,2)>=1,1,0),"X") -> X
A31: 30 | F31: =IF(ISNUMBER($C31),IF(MOD($C31,64)/32>=1,1,0),"") | G31: =IF(ISNUMBER($C31),IF(MOD($C31,2)>=1,1,0),"") | H31: =IF(ISNUMBER($D31),IF(MOD($D31,8)/4>=1,1,0),"") | I31: =IF(ISNUMBER($D31),IF(MOD($D31,4)/2>=1,1,0),"") | J31: =IF(ISNUMBER($D31),IF(MOD($D31,2)>=1,1,0),"") | K31: =IF(ISBLANK($E31),"",IF(MOD(HEX2DEC($E31),32)/16>=1,1,0)) | L31: =IF(ISBLANK($E31),"",IF(MOD(HEX2DEC($E31),16)/8>=1,1,0)) | M31: =IF(ISBLANK($E31),"",IF(MOD(HEX2DEC($E31),8)/4>=1,1,0)) | N31: =IF(ISBLANK($E31),"",IF(MOD(HEX2DEC($E31),4)/2>=1,1,0)) | O31: =IF(ISBLANK($E31),"",IF(MOD(HEX2DEC($E31),2)>=1,1,0)) | Q31: =IF(ISNUMBER($P31),IF(MOD($P31,16)/8>=1,1,0),"X") -> X | R31: =IF(ISNUMBER($P31),IF(MOD($P31,8)/4>=1,1,0),"X") -> X | S31: =IF(ISNUMBER($P31),IF(MOD($P31,4)/2>=1,1,0),"X") -> X | T31: =IF(ISNUMBER($P31),IF(MOD($P31,2)>=1,1,0),"X") -> X
A32: 31 | F32: =IF(ISNUMBER($C32),IF(MOD($C32,64)/32>=1,1,0),"") | G32: =IF(ISNUMBER($C32),IF(MOD($C32,2)>=1,1,0),"") | H32: =IF(ISNUMBER($D32),IF(MOD($D32,8)/4>=1,1,0),"") | I32: =IF(ISNUMBER($D32),IF(MOD($D32,4)/2>=1,1,0),"") | J32: =IF(ISNUMBER($D32),IF(MOD($D32,2)>=1,1,0),"") | K32: =IF(ISBLANK($E32),"",IF(MOD(HEX2DEC($E32),32)/16>=1,1,0)) | L32: =IF(ISBLANK($E32),"",IF(MOD(HEX2DEC($E32),16)/8>=1,1,0)) | M32: =IF(ISBLANK($E32),"",IF(MOD(HEX2DEC($E32),8)/4>=1,1,0)) | N32: =IF(ISBLANK($E32),"",IF(MOD(HEX2DEC($E32),4)/2>=1,1,0)) | O32: =IF(ISBLANK($E32),"",IF(MOD(HEX2DEC($E32),2)>=1,1,0)) | Q32: =IF(ISNUMBER($P32),IF(MOD($P32,16)/8>=1,1,0),"X") -> X | R32: =IF(ISNUMBER($P32),IF(MOD($P32,8)/4>=1,1,0),"X") -> X | S32: =IF(ISNUMBER($P32),IF(MOD($P32,4)/2>=1,1,0),"X") -> X | T32: =IF(ISNUMBER($P32),IF(MOD($P32,2)>=1,1,0),"X") -> X
A33: 32 | F33: =IF(ISNUMBER($C33),IF(MOD($C33,64)/32>=1,1,0),"") | G33: =IF(ISNUMBER($C33),IF(MOD($C33,2)>=1,1,0),"") | H33: =IF(ISNUMBER($D33),IF(MOD($D33,8)/4>=1,1,0),"") | I33: =IF(ISNUMBER($D33),IF(MOD($D33,4)/2>=1,1,0),"") | J33: =IF(ISNUMBER($D33),IF(MOD($D33,2)>=1,1,0),"") | K33: =IF(ISBLANK($E33),"",IF(MOD(HEX2DEC($E33),32)/16>=1,1,0)) | L33: =IF(ISBLANK($E33),"",IF(MOD(HEX2DEC($E33),16)/8>=1,1,0)) | M33: =IF(ISBLANK($E33),"",IF(MOD(HEX2DEC($E33),8)/4>=1,1,0)) | N33: =IF(ISBLANK($E33),"",IF(MOD(HEX2DEC($E33),4)/2>=1,1,0)) | O33: =IF(ISBLANK($E33),"",IF(MOD(HEX2DEC($E33),2)>=1,1,0)) | Q33: =IF(ISNUMBER($P33),IF(MOD($P33,16)/8>=1,1,0),"X") -> X | R33: =IF(ISNUMBER($P33),IF(MOD($P33,8)/4>=1,1,0),"X") -> X | S33: =IF(ISNUMBER($P33),IF(MOD($P33,4)/2>=1,1,0),"X") -> X | T33: =IF(ISNUMBER($P33),IF(MOD($P33,2)>=1,1,0),"X") -> X
A34: 33 | F34: =IF(ISNUMBER($C34),IF(MOD($C34,64)/32>=1,1,0),"") | G34: =IF(ISNUMBER($C34),IF(MOD($C34,2)>=1,1,0),"") | H34: =IF(ISNUMBER($D34),IF(MOD($D34,8)/4>=1,1,0),"") | I34: =IF(ISNUMBER($D34),IF(MOD($D34,4)/2>=1,1,0),"") | J34: =IF(ISNUMBER($D34),IF(MOD($D34,2)>=1,1,0),"") | K34: =IF(ISBLANK($E34),"",IF(MOD(HEX2DEC($E34),32)/16>=1,1,0)) | L34: =IF(ISBLANK($E34),"",IF(MOD(HEX2DEC($E34),16)/8>=1,1,0)) | M34: =IF(ISBLANK($E34),"",IF(MOD(HEX2DEC($E34),8)/4>=1,1,0)) | N34: =IF(ISBLANK($E34),"",IF(MOD(HEX2DEC($E34),4)/2>=1,1,0)) | O34: =IF(ISBLANK($E34),"",IF(MOD(HEX2DEC($E34),2)>=1,1,0)) | Q34: =IF(ISNUMBER($P34),IF(MOD($P34,16)/8>=1,1,0),"X") -> X | R34: =IF(ISNUMBER($P34),IF(MOD($P34,8)/4>=1,1,0),"X") -> X | S34: =IF(ISNUMBER($P34),IF(MOD($P34,4)/2>=1,1,0),"X") -> X | T34: =IF(ISNUMBER($P34),IF(MOD($P34,2)>=1,1,0),"X") -> X
A35: 34 | F35: =IF(ISNUMBER($C35),IF(MOD($C35,64)/32>=1,1,0),"") | G35: =IF(ISNUMBER($C35),IF(MOD($C35,2)>=1,1,0),"") | H35: =IF(ISNUMBER($D35),IF(MOD($D35,8)/4>=1,1,0),"") | I35: =IF(ISNUMBER($D35),IF(MOD($D35,4)/2>=1,1,0),"") | J35: =IF(ISNUMBER($D35),IF(MOD($D35,2)>=1,1,0),"") | K35: =IF(ISBLANK($E35),"",IF(MOD(HEX2DEC($E35),32)/16>=1,1,0)) | L35: =IF(ISBLANK($E35),"",IF(MOD(HEX2DEC($E35),16)/8>=1,1,0)) | M35: =IF(ISBLANK($E35),"",IF(MOD(HEX2DEC($E35),8)/4>=1,1,0)) | N35: =IF(ISBLANK($E35),"",IF(MOD(HEX2DEC($E35),4)/2>=1,1,0)) | O35: =IF(ISBLANK($E35),"",IF(MOD(HEX2DEC($E35),2)>=1,1,0)) | Q35: =IF(ISNUMBER($P35),IF(MOD($P35,16)/8>=1,1,0),"X") -> X | R35: =IF(ISNUMBER($P35),IF(MOD($P35,8)/4>=1,1,0),"X") -> X | S35: =IF(ISNUMBER($P35),IF(MOD($P35,4)/2>=1,1,0),"X") -> X | T35: =IF(ISNUMBER($P35),IF(MOD($P35,2)>=1,1,0),"X") -> X
F36: =IF(ISNUMBER($C36),IF(MOD($C36,64)/32>=1,1,0),"") | G36: =IF(ISNUMBER($C36),IF(MOD($C36,2)>=1,1,0),"") | H36: =IF(ISNUMBER($D36),IF(MOD($D36,8)/4>=1,1,0),"") | I36: =IF(ISNUMBER($D36),IF(MOD($D36,4)/2>=1,1,0),"") | J36: =IF(ISNUMBER($D36),IF(MOD($D36,2)>=1,1,0),"") | K36: =IF(ISBLANK($E36),"",IF(MOD(HEX2DEC($E36),32)/16>=1,1,0)) | L36: =IF(ISBLANK($E36),"",IF(MOD(HEX2DEC($E36),16)/8>=1,1,0)) | M36: =IF(ISBLANK($E36),"",IF(MOD(HEX2DEC($E36),8)/4>=1,1,0)) | N36: =IF(ISBLANK($E36),"",IF(MOD(HEX2DEC($E36),4)/2>=1,1,0)) | O36: =IF(ISBLANK($E36),"",IF(MOD(HEX2DEC($E36),2)>=1,1,0))
F37: =IF(ISNUMBER($C37),IF(MOD($C37,64)/32>=1,1,0),"") | G37: =IF(ISNUMBER($C37),IF(MOD($C37,2)>=1,1,0),"") | H37: =IF(ISNUMBER($D37),IF(MOD($D37,8)/4>=1,1,0),"") | I37: =IF(ISNUMBER($D37),IF(MOD($D37,4)/2>=1,1,0),"") | J37: =IF(ISNUMBER($D37),IF(MOD($D37,2)>=1,1,0),"") | K37: =IF(ISBLANK($E37),"",IF(MOD(HEX2DEC($E37),32)/16>=1,1,0)) | L37: =IF(ISBLANK($E37),"",IF(MOD(HEX2DEC($E37),16)/8>=1,1,0)) | M37: =IF(ISBLANK($E37),"",IF(MOD(HEX2DEC($E37),8)/4>=1,1,0)) | N37: =IF(ISBLANK($E37),"",IF(MOD(HEX2DEC($E37),4)/2>=1,1,0)) | O37: =IF(ISBLANK($E37),"",IF(MOD(HEX2DEC($E37),2)>=1,1,0))
F38: =IF(ISNUMBER($C38),IF(MOD($C38,64)/32>=1,1,0),"") | G38: =IF(ISNUMBER($C38),IF(MOD($C38,2)>=1,1,0),"") | H38: =IF(ISNUMBER($D38),IF(MOD($D38,8)/4>=1,1,0),"") | I38: =IF(ISNUMBER($D38),IF(MOD($D38,4)/2>=1,1,0),"") | J38: =IF(ISNUMBER($D38),IF(MOD($D38,2)>=1,1,0),"") | K38: =IF(ISBLANK($E38),"",IF(MOD(HEX2DEC($E38),32)/16>=1,1,0)) | L38: =IF(ISBLANK($E38),"",IF(MOD(HEX2DEC($E38),16)/8>=1,1,0)) | M38: =IF(ISBLANK($E38),"",IF(MOD(HEX2DEC($E38),8)/4>=1,1,0)) | N38: =IF(ISBLANK($E38),"",IF(MOD(HEX2DEC($E38),4)/2>=1,1,0)) | O38: =IF(ISBLANK($E38),"",IF(MOD(HEX2DEC($E38),2)>=1,1,0))
F39: =IF(ISNUMBER($C39),IF(MOD($C39,64)/32>=1,1,0),"") | G39: =IF(ISNUMBER($C39),IF(MOD($C39,2)>=1,1,0),"") | H39: =IF(ISNUMBER($D39),IF(MOD($D39,8)/4>=1,1,0),"") | I39: =IF(ISNUMBER($D39),IF(MOD($D39,4)/2>=1,1,0),"") | J39: =IF(ISNUMBER($D39),IF(MOD($D39,2)>=1,1,0),"") | K39: =IF(ISBLANK($E39),"",IF(MOD(HEX2DEC($E39),32)/16>=1,1,0)) | L39: =IF(ISBLANK($E39),"",IF(MOD(HEX2DEC($E39),16)/8>=1,1,0)) | M39: =IF(ISBLANK($E39),"",IF(MOD(HEX2DEC($E39),8)/4>=1,1,0)) | N39: =IF(ISBLANK($E39),"",IF(MOD(HEX2DEC($E39),4)/2>=1,1,0)) | O39: =IF(ISBLANK($E39),"",IF(MOD(HEX2DEC($E39),2)>=1,1,0))
F40: =IF(ISNUMBER($C40),IF(MOD($C40,64)/32>=1,1,0),"") | G40: =IF(ISNUMBER($C40),IF(MOD($C40,2)>=1,1,0),"") | H40: =IF(ISNUMBER($D40),IF(MOD($D40,8)/4>=1,1,0),"") | I40: =IF(ISNUMBER($D40),IF(MOD($D40,4)/2>=1,1,0),"") | J40: =IF(ISNUMBER($D40),IF(MOD($D40,2)>=1,1,0),"") | K40: =IF(ISBLANK($E40),"",IF(MOD(HEX2DEC($E40),32)/16>=1,1,0)) | L40: =IF(ISBLANK($E40),"",IF(MOD(HEX2DEC($E40),16)/8>=1,1,0)) | M40: =IF(ISBLANK($E40),"",IF(MOD(HEX2DEC($E40),8)/4>=1,1,0)) | N40: =IF(ISBLANK($E40),"",IF(MOD(HEX2DEC($E40),4)/2>=1,1,0)) | O40: =IF(ISBLANK($E40),"",IF(MOD(HEX2DEC($E40),2)>=1,1,0))
...

Sheet 控制信号表达式生成
A1: 指令 | B1: =真值表!C1 -> Funct7 (十进制) | C1: =真值表!D1 -> Funct3 (十进制) | D1: =真值表!E1 -> OpCode (十六进制) | E1: =真值表!F1 -> F30 | F1: =真值表!G1 -> F25 | G1: =真值表!H1 -> F14 | H1: =真值表!I1 -> F13 | I1: =真值表!J1 -> F12 | ... N1: =真值表!O1 -> OP2 | O1: 逻辑表达式最小项 | P1: =真值表!Q1 -> S3 | Q1: =真值表!R1 -> S2 | R1: =真值表!S1 -> S1 | S1: =真值表!T1 -> S0 | T1: =真值表!U1 -> MemtoReg | U1: =真值表!V1 -> MemWrite | V1: =真值表!W1 -> ALU_Src | W1: =真值表!X1 -> RegWrite | ... AL1: =真值表!AM1 -> XXX
A2: =IF(ISBLANK(真值表!B2),"",真值表!B2) -> add | B2: =IF(ISBLANK(真值表!C2),"",真值表!C2) -> 0 | C2: =IF(ISBLANK(真值表!D2),"",真值表!D2) -> 0 | D2: =IF(ISBLANK(真值表!E2),"",真值表!E2) -> C | E2: =IF(真值表!F2=1," "&真值表!F$1&"&",IF(真值表!F2=0,"~"&真值表!F$1&"&","")) -> ~F30& | F2: =IF(真值表!G2=1," "&真值表!G$1&"&",IF(真值表!G2=0,"~"&真值表!G$1&"&","")) -> ~F25& | G2: =IF(真值表!H2=1," "&真值表!H$1&"&",IF(真值表!H2=0,"~"&真值表!H$1&"&","")) -> ~F14& | H2: =IF(真值表!I2=1," "&真值表!I$1&"&",IF(真值表!I2=0,"~"&真值表!I$1&"&","")) -> ~F13& | I2: =IF(真值表!J2=1," "&真值表!J$1&"&",IF(真值表!J2=0,"~"&真值表!J$1&"&","")) -> ~F12& | J2: =IF(真值表!K2=1," "&真值表!K$1&"&",IF(真值表!K2=0,"~"&真值表!K$1&"&","")) -> ~OP6& | K2: =IF(真值表!L2=1," "&真值表!L$1&"&",IF(真值表!L2=0,"~"&真值表!L$1&"&","")) -> OP5& | L2: =IF(真值表!M2=1," "&真值表!M$1&"&",IF(真值表!M2=0,"~"&真值表!M$1&"&","")) -> OP4& | ... N2: =IF(真值表!O2=1," "&真值表!O$1&"&",IF(真值表!O2=0,"~"&真值表!O$1&"&","")) -> ~OP2& | O2: =IF(LEN(CONCATENATE(E2,F2,G2,H2,I2,J2,K2,L2,M2,N2))=0,"",LEFT(CONCATENATE(E2,F2,G2,H2,I2,J2,K2,L2,M2,N2),LEN(CONCATENATE(E2,F2,G2,H2,I2,J2,K2,L2,M2,N2))-1)) -> ~F30&~F25&~F14&~F13&~F12&~OP6& OP5& OP4&~OP3&~OP2 | P2: =IF(真值表!Q2=1,$O2&"+","") | Q2: =IF(真值表!R2=1,$O2&"+","") -> ~F30&~F25&~F14&~F13&~F12&~OP6& OP5& OP4&~OP3&~OP2+ | R2: =IF(真值表!S2=1,$O2&"+","") | S2: =IF(真值表!T2=1,$O2&"+","") -> ~F30&~F25&~F14&~F13&~F12&~OP6& OP5& OP4&~OP3&~OP2+ | T2: =IF(真值表!U2=1,$O2&"+","") | U2: =IF(真值表!V2=1,$O2&"+","") | V2: =IF(真值表!W2=1,$O2&"+","") | W2: =IF(真值表!X2=1,$O2&"+","") -> ~F30&~F25&~F14&~F13&~F12&~OP6& OP5& OP4&~OP3&~OP2+ | ... AL2: =IF(真值表!AM2=1,$O2&"+","")
A3: =IF(ISBLANK(真值表!B3),"",真值表!B3) -> sub | B3: =IF(ISBLANK(真值表!C3),"",真值表!C3) -> 32 | C3: =IF(ISBLANK(真值表!D3),"",真值表!D3) -> 0 | D3: =IF(ISBLANK(真值表!E3),"",真值表!E3) -> C | E3: =IF(真值表!F3=1," "&真值表!F$1&"&",IF(真值表!F3=0,"~"&真值表!F$1&"&","")) -> F30& | F3: =IF(真值表!G3=1," "&真值表!G$1&"&",IF(真值表!G3=0,"~"&真值表!G$1&"&","")) -> ~F25& | G3: =IF(真值表!H3=1," "&真值表!H$1&"&",IF(真值表!H3=0,"~"&真值表!H$1&"&","")) -> ~F14& | H3: =IF(真值表!I3=1," "&真值表!I$1&"&",IF(真值表!I3=0,"~"&真值表!I$1&"&","")) -> ~F13& | I3: =IF(真值表!J3=1," "&真值表!J$1&"&",IF(真值表!J3=0,"~"&真值表!J$1&"&","")) -> ~F12& | J3: =IF(真值表!K3=1," "&真值表!K$1&"&",IF(真值表!K3=0,"~"&真值表!K$1&"&","")) -> ~OP6& | K3: =IF(真值表!L3=1," "&真值表!L$1&"&",IF(真值表!L3=0,"~"&真值表!L$1&"&","")) -> OP5& | L3: =IF(真值表!M3=1," "&真值表!M$1&"&",IF(真值表!M3=0,"~"&真值表!M$1&"&","")) -> OP4& | ... N3: =IF(真值表!O3=1," "&真值表!O$1&"&",IF(真值表!O3=0,"~"&真值表!O$1&"&","")) -> ~OP2& | O3: =IF(LEN(CONCATENATE(E3,F3,G3,H3,I3,J3,K3,L3,M3,N3))=0,"",LEFT(CONCATENATE(E3,F3,G3,H3,I3,J3,K3,L3,M3,N3),LEN(CONCATENATE(E3,F3,G3,H3,I3,J3,K3,L3,M3,N3))-1)) -> F30&~F25&~F14&~F13&~F12&~OP6& OP5& OP4&~OP3&~OP2 | P3: =IF(真值表!Q3=1,$O3&"+","") | Q3: =IF(真值表!R3=1,$O3&"+","") -> F30&~F25&~F14&~F13&~F12&~OP6& OP5& OP4&~OP3&~OP2+ | R3: =IF(真值表!S3=1,$O3&"+","") -> F30&~F25&~F14&~F13&~F12&~OP6& OP5& OP4&~OP3&~OP2+ | S3: =IF(真值表!T3=1,$O3&"+","") | T3: =IF(真值表!U3=1,$O3&"+","") | U3: =IF(真值表!V3=1,$O3&"+","") | V3: =IF(真值表!W3=1,$O3&"+","") | W3: =IF(真值表!X3=1,$O3&"+","") -> F30&~F25&~F14&~F13&~F12&~OP6& OP5& OP4&~OP3&~OP2+ | ... AL3: =IF(真值表!AM3=1,$O3&"+","")
A4: =IF(ISBLANK(真值表!B4),"",真值表!B4) -> and | B4: =IF(ISBLANK(真值表!C4),"",真值表!C4) -> 0 | C4: =IF(ISBLANK(真值表!D4),"",真值表!D4) -> 7 | D4: =IF(ISBLANK(真值表!E4),"",真值表!E4) -> C | E4: =IF(真值表!F4=1," "&真值表!F$1&"&",IF(真值表!F4=0,"~"&真值表!F$1&"&","")) -> ~F30& | F4: =IF(真值表!G4=1," "&真值表!G$1&"&",IF(真值表!G4=0,"~"&真值表!G$1&"&","")) -> ~F25& | G4: =IF(真值表!H4=1," "&真值表!H$1&"&",IF(真值表!H4=0,"~"&真值表!H$1&"&","")) -> F14& | H4: =IF(真值表!I4=1," "&真值表!I$1&"&",IF(真值表!I4=0,"~"&真值表!I$1&"&","")) -> F13& | I4: =IF(真值表!J4=1," "&真值表!J$1&"&",IF(真值表!J4=0,"~"&真值表!J$1&"&","")) -> F12& | J4: =IF(真值表!K4=1," "&真值表!K$1&"&",IF(真值表!K4=0,"~"&真值表!K$1&"&","")) -> ~OP6& | K4: =IF(真值表!L4=1," "&真值表!L$1&"&",IF(真值表!L4=0,"~"&真值表!L$1&"&","")) -> OP5& | L4: =IF(真值表!M4=1," "&真值表!M$1&"&",IF(真值表!M4=0,"~"&真值表!M$1&"&","")) -> OP4& | ... N4: =IF(真值表!O4=1," "&真值表!O$1&"&",IF(真值表!O4=0,"~"&真值表!O$1&"&","")) -> ~OP2& | O4: =IF(LEN(CONCATENATE(E4,F4,G4,H4,I4,J4,K4,L4,M4,N4))=0,"",LEFT(CONCATENATE(E4,F4,G4,H4,I4,J4,K4,L4,M4,N4),LEN(CONCATENATE(E4,F4,G4,H4,I4,J4,K4,L4,M4,N4))-1)) -> ~F30&~F25& F14& F13& F12&~OP6& OP5& OP4&~OP3&~OP2 | P4: =IF(真值表!Q4=1,$O4&"+","") | Q4: =IF(真值表!R4=1,$O4&"+","") -> ~F30&~F25& F14& F13& F12&~OP6& OP5& OP4&~OP3&~OP2+ | R4: =IF(真值表!S4=1,$O4&"+","") -> ~F30&~F25& F14& F13& F12&~OP6& OP5& OP4&~OP3&~OP2+ | S4: =IF(真值表!T4=1,$O4&"+","") -> ~F30&~F25& F14& F13& F12&~OP6& OP5& OP4&~OP3&~OP2+ | T4: =IF(真值表!U4=1,$O4&"+","") | U4: =IF(真值表!V4=1,$O4&"+","") | V4: =IF(真值表!W4=1,$O4&"+","") | W4: =IF(真值表!X4=1,$O4&"+","") -> ~F30&~F25& F14& F13& F12&~OP6& OP5& OP4&~OP3&~OP2+ | ... AL4: =IF(真值表!AM4=1,$O4&"+","")
A5: =IF(ISBLANK(真值表!B5),"",真值表!B5) -> or | B5: =IF(ISBLANK(真值表!C5),"",真值表!C5) -> 0 | C5: =IF(ISBLANK(真值表!D5),"",真值表!D5) -> 6 | D5: =IF(ISBLANK(真值表!E5),"",真值表!E5) -> C | E5: =IF(真值表!F5=1," "&真值表!F$1&"&",IF(真值表!F5=0,"~"&真值表!F$1&"&","")) -> ~F30& | F5: =IF(真值表!G5=1," "&真值表!G$1&"&",IF(真值表!G5=0,"~"&真值表!G$1&"&","")) -> ~F25& | G5: =IF(真值表!H5=1," "&真值表!H$1&"&",IF(真值表!H5=0,"~"&真值表!H$1&"&","")) -> F14& | H5: =IF(真值表!I5=1," "&真值表!I$1&"&",IF(真值表!I5=0,"~"&真值表!I$1&"&","")) -> F13& | I5: =IF(真值表!J5=1," "&真值表!J$1&"&",IF(真值表!J5=0,"~"&真值表!J$1&"&","")) -> ~F12& | J5: =IF(真值表!K5=1," "&真值表!K$1&"&",IF(真值表!K5=0,"~"&真值表!K$1&"&","")) -> ~OP6& | K5: =IF(真值表!L5=1," "&真值表!L$1&"&",IF(真值表!L5=0,"~"&真值表!L$1&"&","")) -> OP5& | L5: =IF(真值表!M5=1," "&真值表!M$1&"&",IF(真值表!M5=0,"~"&真值表!M$1&"&","")) -> OP4& | ... N5: =IF(真值表!O5=1," "&真值表!O$1&"&",IF(真值表!O5=0,"~"&真值表!O$1&"&","")) -> ~OP2& | O5: =IF(LEN(CONCATENATE(E5,F5,G5,H5,I5,J5,K5,L5,M5,N5))=0,"",LEFT(CONCATENATE(E5,F5,G5,H5,I5,J5,K5,L5,M5,N5),LEN(CONCATENATE(E5,F5,G5,H5,I5,J5,K5,L5,M5,N5))-1)) -> ~F30&~F25& F14& F13&~F12&~OP6& OP5& OP4&~OP3&~OP2 | P5: =IF(真值表!Q5=1,$O5&"+","") -> ~F30&~F25& F14& F13&~F12&~OP6& OP5& OP4&~OP3&~OP2+ | Q5: =IF(真值表!R5=1,$O5&"+","") | R5: =IF(真值表!S5=1,$O5&"+","") | S5: =IF(真值表!T5=1,$O5&"+","") | T5: =IF(真值表!U5=1,$O5&"+","") | U5: =IF(真值表!V5=1,$O5&"+","") | V5: =IF(真值表!W5=1,$O5&"+","") | W5: =IF(真值表!X5=1,$O5&"+","") -> ~F30&~F25& F14& F13&~F12&~OP6& OP5& OP4&~OP3&~OP2+ | ... AL5: =IF(真值表!AM5=1,$O5&"+","")
A6: =IF(ISBLANK(真值表!B6),"",真值表!B6) -> slt | B6: =IF(ISBLANK(真值表!C6),"",真值表!C6) -> 0 | C6: =IF(ISBLANK(真值表!D6),"",真值表!D6) -> 2 | D6: =IF(ISBLANK(真值表!E6),"",真值表!E6) -> C | E6: =IF(真值表!F6=1," "&真值表!F$1&"&",IF(真值表!F6=0,"~"&真值表!F$1&"&","")) -> ~F30& | F6: =IF(真值表!G6=1," "&真值表!G$1&"&",IF(真值表!G6=0,"~"&真值表!G$1&"&","")) -> ~F25& | G6: =IF(真值表!H6=1," "&真值表!H$1&"&",IF(真值表!H6=0,"~"&真值表!H$1&"&","")) -> ~F14& | H6: =IF(真值表!I6=1," "&真值表!I$1&"&",IF(真值表!I6=0,"~"&真值表!I$1&"&","")) -> F13& | I6: =IF(真值表!J6=1," "&真值表!J$1&"&",IF(真值表!J6=0,"~"&真值表!J$1&"&","")) -> ~F12& | J6: =IF(真值表!K6=1," "&真值表!K$1&"&",IF(真值表!K6=0,"~"&真值表!K$1&"&","")) -> ~OP6& | K6: =IF(真值表!L6=1," "&真值表!L$1&"&",IF(真值表!L6=0,"~"&真值表!L$1&"&","")) -> OP5& | L6: =IF(真值表!M6=1," "&真值表!M$1&"&",IF(真值表!M6=0,"~"&真值表!M$1&"&","")) -> OP4& | ... N6: =IF(真值表!O6=1," "&真值表!O$1&"&",IF(真值表!O6=0,"~"&真值表!O$1&"&","")) -> ~OP2& | O6: =IF(LEN(CONCATENATE(E6,F6,G6,H6,I6,J6,K6,L6,M6,N6))=0,"",LEFT(CONCATENATE(E6,F6,G6,H6,I6,J6,K6,L6,M6,N6),LEN(CONCATENATE(E6,F6,G6,H6,I6,J6,K6,L6,M6,N6))-1)) -> ~F30&~F25&~F14& F13&~F12&~OP6& OP5& OP4&~OP3&~OP2 | P6: =IF(真值表!Q6=1,$O6&"+","") -> ~F30&~F25&~F14& F13&~F12&~OP6& OP5& OP4&~OP3&~OP2+ | Q6: =IF(真值表!R6=1,$O6&"+","") | R6: =IF(真值表!S6=1,$O6&"+","") -> ~F30&~F25&~F14& F13&~F12&~OP6& OP5& OP4&~OP3&~OP2+ | S6: =IF(真值表!T6=1,$O6&"+","") -> ~F30&~F25&~F14& F13&~F12&~OP6& OP5& OP4&~OP3&~OP2+ | T6: =IF(真值表!U6=1,$O6&"+","") | U6: =IF(真值表!V6=1,$O6&"+","") | V6: =IF(真值表!W6=1,$O6&"+","") | W6: =IF(真值表!X6=1,$O6&"+","") -> ~F30&~F25&~F14& F13&~F12&~OP6& OP5& OP4&~OP3&~OP2+ | ... AL6: =IF(真值表!AM6=1,$O6&"+","")
A7: =IF(ISBLANK(真值表!B7),"",真值表!B7) -> sltu | B7: =IF(ISBLANK(真值表!C7),"",真值表!C7) -> 0 | C7: =IF(ISBLANK(真值表!D7),"",真值表!D7) -> 3 | D7: =IF(ISBLANK(真值表!E7),"",真值表!E7) -> C | E7: =IF(真值表!F7=1," "&真值表!F$1&"&",IF(真值表!F7=0,"~"&真值表!F$1&"&","")) -> ~F30& | F7: =IF(真值表!G7=1," "&真值表!G$1&"&",IF(真值表!G7=0,"~"&真值表!G$1&"&","")) -> ~F25& | G7: =IF(真值表!H7=1," "&真值表!H$1&"&",IF(真值表!H7=0,"~"&真值表!H$1&"&","")) -> ~F14& | H7: =IF(真值表!I7=1," "&真值表!I$1&"&",IF(真值表!I7=0,"~"&真值表!I$1&"&","")) -> F13& | I7: =IF(真值表!J7=1," "&真值表!J$1&"&",IF(真值表!J7=0,"~"&真值表!J$1&"&","")) -> F12& | J7: =IF(真值表!K7=1," "&真值表!K$1&"&",IF(真值表!K7=0,"~"&真值表!K$1&"&","")) -> ~OP6& | K7: =IF(真值表!L7=1," "&真值表!L$1&"&",IF(真值表!L7=0,"~"&真值表!L$1&"&","")) -> OP5& | L7: =IF(真值表!M7=1," "&真值表!M$1&"&",IF(真值表!M7=0,"~"&真值表!M$1&"&","")) -> OP4& | ... N7: =IF(真值表!O7=1," "&真值表!O$1&"&",IF(真值表!O7=0,"~"&真值表!O$1&"&","")) -> ~OP2& | O7: =IF(LEN(CONCATENATE(E7,F7,G7,H7,I7,J7,K7,L7,M7,N7))=0,"",LEFT(CONCATENATE(E7,F7,G7,H7,I7,J7,K7,L7,M7,N7),LEN(CONCATENATE(E7,F7,G7,H7,I7,J7,K7,L7,M7,N7))-1)) -> ~F30&~F25&~F14& F13& F12&~OP6& OP5& OP4&~OP3&~OP2 | P7: =IF(真值表!Q7=1,$O7&"+","") -> ~F30&~F25&~F14& F13& F12&~OP6& OP5& OP4&~OP3&~OP2+ | Q7: =IF(真值表!R7=1,$O7&"+","") -> ~F30&~F25&~F14& F13& F12&~OP6& OP5& OP4&~OP3&~OP2+ | R7: =IF(真值表!S7=1,$O7&"+","") | S7: =IF(真值表!T7=1,$O7&"+","") | T7: =IF(真值表!U7=1,$O7&"+","") | U7: =IF(真值表!V7=1,$O7&"+","") | V7: =IF(真值表!W7=1,$O7&"+","") | W7: =IF(真值表!X7=1,$O7&"+","") -> ~F30&~F25&~F14& F13& F12&~OP6& OP5& OP4&~OP3&~OP2+ | ... AL7: =IF(真值表!AM7=1,$O7&"+","")
A8: =IF(ISBLANK(真值表!B8),"",真值表!B8) -> addi | B8: =IF(ISBLANK(真值表!C8),"",真值表!C8) | C8: =IF(ISBLANK(真值表!D8),"",真值表!D8) -> 0 | D8: =IF(ISBLANK(真值表!E8),"",真值表!E8) -> 4 | E8: =IF(真值表!F8=1," "&真值表!F$1&"&",IF(真值表!F8=0,"~"&真值表!F$1&"&","")) | F8: =IF(真值表!G8=1," "&真值表!G$1&"&",IF(真值表!G8=0,"~"&真值表!G$1&"&","")) | G8: =IF(真值表!H8=1," "&真值表!H$1&"&",IF(真值表!H8=0,"~"&真值表!H$1&"&","")) -> ~F14& | H8: =IF(真值表!I8=1," "&真值表!I$1&"&",IF(真值表!I8=0,"~"&真值表!I$1&"&","")) -> ~F13& | I8: =IF(真值表!J8=1," "&真值表!J$1&"&",IF(真值表!J8=0,"~"&真值表!J$1&"&","")) -> ~F12& | J8: =IF(真值表!K8=1," "&真值表!K$1&"&",IF(真值表!K8=0,"~"&真值表!K$1&"&","")) -> ~OP6& | K8: =IF(真值表!L8=1," "&真值表!L$1&"&",IF(真值表!L8=0,"~"&真值表!L$1&"&","")) -> ~OP5& | L8: =IF(真值表!M8=1," "&真值表!M$1&"&",IF(真值表!M8=0,"~"&真值表!M$1&"&","")) -> OP4& | ... N8: =IF(真值表!O8=1," "&真值表!O$1&"&",IF(真值表!O8=0,"~"&真值表!O$1&"&","")) -> ~OP2& | O8: =IF(LEN(CONCATENATE(E8,F8,G8,H8,I8,J8,K8,L8,M8,N8))=0,"",LEFT(CONCATENATE(E8,F8,G8,H8,I8,J8,K8,L8,M8,N8),LEN(CONCATENATE(E8,F8,G8,H8,I8,J8,K8,L8,M8,N8))-1)) -> ~F14&~F13&~F12&~OP6&~OP5& OP4&~OP3&~OP2 | P8: =IF(真值表!Q8=1,$O8&"+","") | Q8: =IF(真值表!R8=1,$O8&"+","") -> ~F14&~F13&~F12&~OP6&~OP5& OP4&~OP3&~OP2+ | R8: =IF(真值表!S8=1,$O8&"+","") | S8: =IF(真值表!T8=1,$O8&"+","") -> ~F14&~F13&~F12&~OP6&~OP5& OP4&~OP3&~OP2+ | T8: =IF(真值表!U8=1,$O8&"+","") | U8: =IF(真值表!V8=1,$O8&"+","") | V8: =IF(真值表!W8=1,$O8&"+","") -> ~F14&~F13&~F12&~OP6&~OP5& OP4&~OP3&~OP2+ | W8: =IF(真值表!X8=1,$O8&"+","") -> ~F14&~F13&~F12&~OP6&~OP5& OP4&~OP3&~OP2+ | ... AL8: =IF(真值表!AM8=1,$O8&"+","")
A9: =IF(ISBLANK(真值表!B9),"",真值表!B9) -> andi | B9: =IF(ISBLANK(真值表!C9),"",真值表!C9) | C9: =IF(ISBLANK(真值表!D9),"",真值表!D9) -> 7 | D9: =IF(ISBLANK(真值表!E9),"",真值表!E9) -> 4 | E9: =IF(真值表!F9=1," "&真值表!F$1&"&",IF(真值表!F9=0,"~"&真值表!F$1&"&","")) | F9: =IF(真值表!G9=1," "&真值表!G$1&"&",IF(真值表!G9=0,"~"&真值表!G$1&"&","")) | G9: =IF(真值表!H9=1," "&真值表!H$1&"&",IF(真值表!H9=0,"~"&真值表!H$1&"&","")) -> F14& | H9: =IF(真值表!I9=1," "&真值表!I$1&"&",IF(真值表!I9=0,"~"&真值表!I$1&"&","")) -> F13& | I9: =IF(真值表!J9=1," "&真值表!J$1&"&",IF(真值表!J9=0,"~"&真值表!J$1&"&","")) -> F12& | J9: =IF(真值表!K9=1," "&真值表!K$1&"&",IF(真值表!K9=0,"~"&真值表!K$1&"&","")) -> ~OP6& | K9: =IF(真值表!L9=1," "&真值表!L$1&"&",IF(真值表!L9=0,"~"&真值表!L$1&"&","")) -> ~OP5& | L9: =IF(真值表!M9=1," "&真值表!M$1&"&",IF(真值表!M9=0,"~"&真值表!M$1&"&","")) -> OP4& | ... N9: =IF(真值表!O9=1," "&真值表!O$1&"&",IF(真值表!O9=0,"~"&真值表!O$1&"&","")) -> ~OP2& | O9: =IF(LEN(CONCATENATE(E9,F9,G9,H9,I9,J9,K9,L9,M9,N9))=0,"",LEFT(CONCATENATE(E9,F9,G9,H9,I9,J9,K9,L9,M9,N9),LEN(CONCATENATE(E9,F9,G9,H9,I9,J9,K9,L9,M9,N9))-1)) -> F14& F13& F12&~OP6&~OP5& OP4&~OP3&~OP2 | P9: =IF(真值表!Q9=1,$O9&"+","") | Q9: =IF(真值表!R9=1,$O9&"+","") -> F14& F13& F12&~OP6&~OP5& OP4&~OP3&~OP2+ | R9: =IF(真值表!S9=1,$O9&"+","") -> F14& F13& F12&~OP6&~OP5& OP4&~OP3&~OP2+ | S9: =IF(真值表!T9=1,$O9&"+","") -> F14& F13& F12&~OP6&~OP5& OP4&~OP3&~OP2+ | T9: =IF(真值表!U9=1,$O9&"+","") | U9: =IF(真值表!V9=1,$O9&"+","") | V9: =IF(真值表!W9=1,$O9&"+","") -> F14& F13& F12&~OP6&~OP5& OP4&~OP3&~OP2+ | W9: =IF(真值表!X9=1,$O9&"+","") -> F14& F13& F12&~OP6&~OP5& OP4&~OP3&~OP2+ | ... AL9: =IF(真值表!AM9=1,$O9&"+","")
A10: =IF(ISBLANK(真值表!B10),"",真值表!B10) -> ori | B10: =IF(ISBLANK(真值表!C10),"",真值表!C10) | C10: =IF(ISBLANK(真值表!D10),"",真值表!D10) -> 6 | D10: =IF(ISBLANK(真值表!E10),"",真值表!E10) -> 4 | E10: =IF(真值表!F10=1," "&真值表!F$1&"&",IF(真值表!F10=0,"~"&真值表!F$1&"&","")) | F10: =IF(真值表!G10=1," "&真值表!G$1&"&",IF(真值表!G10=0,"~"&真值表!G$1&"&","")) | G10: =IF(真值表!H10=1," "&真值表!H$1&"&",IF(真值表!H10=0,"~"&真值表!H$1&"&","")) -> F14& | H10: =IF(真值表!I10=1," "&真值表!I$1&"&",IF(真值表!I10=0,"~"&真值表!I$1&"&","")) -> F13& | I10: =IF(真值表!J10=1," "&真值表!J$1&"&",IF(真值表!J10=0,"~"&真值表!J$1&"&","")) -> ~F12& | J10: =IF(真值表!K10=1," "&真值表!K$1&"&",IF(真值表!K10=0,"~"&真值表!K$1&"&","")) -> ~OP6& | K10: =IF(真值表!L10=1," "&真值表!L$1&"&",IF(真值表!L10=0,"~"&真值表!L$1&"&","")) -> ~OP5& | L10: =IF(真值表!M10=1," "&真值表!M$1&"&",IF(真值表!M10=0,"~"&真值表!M$1&"&","")) -> OP4& | ... N10: =IF(真值表!O10=1," "&真值表!O$1&"&",IF(真值表!O10=0,"~"&真值表!O$1&"&","")) -> ~OP2& | O10: =IF(LEN(CONCATENATE(E10,F10,G10,H10,I10,J10,K10,L10,M10,N10))=0,"",LEFT(CONCATENATE(E10,F10,G10,H10,I10,J10,K10,L10,M10,N10),LEN(CONCATENATE(E10,F10,G10,H10,I10,J10,K10,L10,M10,N10))-1)) -> F14& F13&~F12&~OP6&~OP5& OP4&~OP3&~OP2 | P10: =IF(真值表!Q10=1,$O10&"+","") -> F14& F13&~F12&~OP6&~OP5& OP4&~OP3&~OP2+ | Q10: =IF(真值表!R10=1,$O10&"+","") | R10: =IF(真值表!S10=1,$O10&"+","") | S10: =IF(真值表!T10=1,$O10&"+","") | T10: =IF(真值表!U10=1,$O10&"+","") | U10: =IF(真值表!V10=1,$O10&"+","") | V10: =IF(真值表!W10=1,$O10&"+","") -> F14& F13&~F12&~OP6&~OP5& OP4&~OP3&~OP2+ | W10: =IF(真值表!X10=1,$O10&"+","") -> F14& F13&~F12&~OP6&~OP5& OP4&~OP3&~OP2+ | ... AL10: =IF(真值表!AM10=1,$O10&"+","")
A11: =IF(ISBLANK(真值表!B11),"",真值表!B11) -> xori | B11: =IF(ISBLANK(真值表!C11),"",真值表!C11) | C11: =IF(ISBLANK(真值表!D11),"",真值表!D11) -> 4 | D11: =IF(ISBLANK(真值表!E11),"",真值表!E11) -> 4 | E11: =IF(真值表!F11=1," "&真值表!F$1&"&",IF(真值表!F11=0,"~"&真值表!F$1&"&","")) | F11: =IF(真值表!G11=1," "&真值表!G$1&"&",IF(真值表!G11=0,"~"&真值表!G$1&"&","")) | G11: =IF(真值表!H11=1," "&真值表!H$1&"&",IF(真值表!H11=0,"~"&真值表!H$1&"&","")) -> F14& | H11: =IF(真值表!I11=1," "&真值表!I$1&"&",IF(真值表!I11=0,"~"&真值表!I$1&"&","")) -> ~F13& | I11: =IF(真值表!J11=1," "&真值表!J$1&"&",IF(真值表!J11=0,"~"&真值表!J$1&"&","")) -> ~F12& | J11: =IF(真值表!K11=1," "&真值表!K$1&"&",IF(真值表!K11=0,"~"&真值表!K$1&"&","")) -> ~OP6& | K11: =IF(真值表!L11=1," "&真值表!L$1&"&",IF(真值表!L11=0,"~"&真值表!L$1&"&","")) -> ~OP5& | L11: =IF(真值表!M11=1," "&真值表!M$1&"&",IF(真值表!M11=0,"~"&真值表!M$1&"&","")) -> OP4& | ... N11: =IF(真值表!O11=1," "&真值表!O$1&"&",IF(真值表!O11=0,"~"&真值表!O$1&"&","")) -> ~OP2& | O11: =IF(LEN(CONCATENATE(E11,F11,G11,H11,I11,J11,K11,L11,M11,N11))=0,"",LEFT(CONCATENATE(E11,F11,G11,H11,I11,J11,K11,L11,M11,N11),LEN(CONCATENATE(E11,F11,G11,H11,I11,J11,K11,L11,M11,N11))-1)) -> F14&~F13&~F12&~OP6&~OP5& OP4&~OP3&~OP2 | P11: =IF(真值表!Q11=1,$O11&"+","") -> F14&~F13&~F12&~OP6&~OP5& OP4&~OP3&~OP2+ | Q11: =IF(真值表!R11=1,$O11&"+","") | R11: =IF(真值表!S11=1,$O11&"+","") | S11: =IF(真值表!T11=1,$O11&"+","") -> F14&~F13&~F12&~OP6&~OP5& OP4&~OP3&~OP2+ | T11: =IF(真值表!U11=1,$O11&"+","") | U11: =IF(真值表!V11=1,$O11&"+","") | V11: =IF(真值表!W11=1,$O11&"+","") -> F14&~F13&~F12&~OP6&~OP5& OP4&~OP3&~OP2+ | W11: =IF(真值表!X11=1,$O11&"+","") -> F14&~F13&~F12&~OP6&~OP5& OP4&~OP3&~OP2+ | ... AL11: =IF(真值表!AM11=1,$O11&"+","")
A12: =IF(ISBLANK(真值表!B12),"",真值表!B12) -> slti | B12: =IF(ISBLANK(真值表!C12),"",真值表!C12) | C12: =IF(ISBLANK(真值表!D12),"",真值表!D12) -> 2 | D12: =IF(ISBLANK(真值表!E12),"",真值表!E12) -> 4 | E12: =IF(真值表!F12=1," "&真值表!F$1&"&",IF(真值表!F12=0,"~"&真值表!F$1&"&","")) | F12: =IF(真值表!G12=1," "&真值表!G$1&"&",IF(真值表!G12=0,"~"&真值表!G$1&"&","")) | G12: =IF(真值表!H12=1," "&真值表!H$1&"&",IF(真值表!H12=0,"~"&真值表!H$1&"&","")) -> ~F14& | H12: =IF(真值表!I12=1," "&真值表!I$1&"&",IF(真值表!I12=0,"~"&真值表!I$1&"&","")) -> F13& | I12: =IF(真值表!J12=1," "&真值表!J$1&"&",IF(真值表!J12=0,"~"&真值表!J$1&"&","")) -> ~F12& | J12: =IF(真值表!K12=1," "&真值表!K$1&"&",IF(真值表!K12=0,"~"&真值表!K$1&"&","")) -> ~OP6& | K12: =IF(真值表!L12=1," "&真值表!L$1&"&",IF(真值表!L12=0,"~"&真值表!L$1&"&","")) -> ~OP5& | L12: =IF(真值表!M12=1," "&真值表!M$1&"&",IF(真值表!M12=0,"~"&真值表!M$1&"&","")) -> OP4& | ... N12: =IF(真值表!O12=1," "&真值表!O$1&"&",IF(真值表!O12=0,"~"&真值表!O$1&"&","")) -> ~OP2& | O12: =IF(LEN(CONCATENATE(E12,F12,G12,H12,I12,J12,K12,L12,M12,N12))=0,"",LEFT(CONCATENATE(E12,F12,G12,H12,I12,J12,K12,L12,M12,N12),LEN(CONCATENATE(E12,F12,G12,H12,I12,J12,K12,L12,M12,N12))-1)) -> ~F14& F13&~F12&~OP6&~OP5& OP4&~OP3&~OP2 | P12: =IF(真值表!Q12=1,$O12&"+","") -> ~F14& F13&~F12&~OP6&~OP5& OP4&~OP3&~OP2+ | Q12: =IF(真值表!R12=1,$O12&"+","") | R12: =IF(真值表!S12=1,$O12&"+","") -> ~F14& F13&~F12&~OP6&~OP5& OP4&~OP3&~OP2+ | S12: =IF(真值表!T12=1,$O12&"+","") -> ~F14& F13&~F12&~OP6&~OP5& OP4&~OP3&~OP2+ | T12: =IF(真值表!U12=1,$O12&"+","") | U12: =IF(真值表!V12=1,$O12&"+","") | V12: =IF(真值表!W12=1,$O12&"+","") -> ~F14& F13&~F12&~OP6&~OP5& OP4&~OP3&~OP2+ | W12: =IF(真值表!X12=1,$O12&"+","") -> ~F14& F13&~F12&~OP6&~OP5& OP4&~OP3&~OP2+ | ... AL12: =IF(真值表!AM12=1,$O12&"+","")
A13: =IF(ISBLANK(真值表!B13),"",真值表!B13) -> slli | B13: =IF(ISBLANK(真值表!C13),"",真值表!C13) -> 0 | C13: =IF(ISBLANK(真值表!D13),"",真值表!D13) -> 1 | D13: =IF(ISBLANK(真值表!E13),"",真值表!E13) -> 4 | E13: =IF(真值表!F13=1," "&真值表!F$1&"&",IF(真值表!F13=0,"~"&真值表!F$1&"&","")) -> ~F30& | F13: =IF(真值表!G13=1," "&真值表!G$1&"&",IF(真值表!G13=0,"~"&真值表!G$1&"&","")) -> ~F25& | G13: =IF(真值表!H13=1," "&真值表!H$1&"&",IF(真值表!H13=0,"~"&真值表!H$1&"&","")) -> ~F14& | H13: =IF(真值表!I13=1," "&真值表!I$1&"&",IF(真值表!I13=0,"~"&真值表!I$1&"&","")) -> ~F13& | I13: =IF(真值表!J13=1," "&真值表!J$1&"&",IF(真值表!J13=0,"~"&真值表!J$1&"&","")) -> F12& | J13: =IF(真值表!K13=1," "&真值表!K$1&"&",IF(真值表!K13=0,"~"&真值表!K$1&"&","")) -> ~OP6& | K13: =IF(真值表!L13=1," "&真值表!L$1&"&",IF(真值表!L13=0,"~"&真值表!L$1&"&","")) -> ~OP5& | L13: =IF(真值表!M13=1," "&真值表!M$1&"&",IF(真值表!M13=0,"~"&真值表!M$1&"&","")) -> OP4& | ... N13: =IF(真值表!O13=1," "&真值表!O$1&"&",IF(真值表!O13=0,"~"&真值表!O$1&"&","")) -> ~OP2& | O13: =IF(LEN(CONCATENATE(E13,F13,G13,H13,I13,J13,K13,L13,M13,N13))=0,"",LEFT(CONCATENATE(E13,F13,G13,H13,I13,J13,K13,L13,M13,N13),LEN(CONCATENATE(E13,F13,G13,H13,I13,J13,K13,L13,M13,N13))-1)) -> ~F30&~F25&~F14&~F13& F12&~OP6&~OP5& OP4&~OP3&~OP2 | P13: =IF(真值表!Q13=1,$O13&"+","") | Q13: =IF(真值表!R13=1,$O13&"+","") | R13: =IF(真值表!S13=1,$O13&"+","") | S13: =IF(真值表!T13=1,$O13&"+","") | T13: =IF(真值表!U13=1,$O13&"+","") | U13: =IF(真值表!V13=1,$O13&"+","") | V13: =IF(真值表!W13=1,$O13&"+","") -> ~F30&~F25&~F14&~F13& F12&~OP6&~OP5& OP4&~OP3&~OP2+ | W13: =IF(真值表!X13=1,$O13&"+","") -> ~F30&~F25&~F14&~F13& F12&~OP6&~OP5& OP4&~OP3&~OP2+ | ... AL13: =IF(真值表!AM13=1,$O13&"+","")
... A57: =IF(ISBLANK(真值表!B57),"",真值表!B57) | B57: =IF(ISBLANK(真值表!C57),"",真值表!C57) | C57: =IF(ISBLANK(真值表!D57),"",真值表!D57) | D57: =IF(ISBLANK(真值表!E57),"",真值表!E57) | E57: =IF(真值表!F57=1," "&真值表!F$1&"&",IF(真值表!F57=0,"~"&真值表!F$1&"&","")) | F57: =IF(真值表!G57=1," "&真值表!G$1&"&",IF(真值表!G57=0,"~"&真值表!G$1&"&","")) | G57: =IF(真值表!H57=1," "&真值表!H$1&"&",IF(真值表!H57=0,"~"&真值表!H$1&"&","")) | H57: =IF(真值表!I57=1," "&真值表!I$1&"&",IF(真值表!I57=0,"~"&真值表!I$1&"&","")) | I57: =IF(真值表!J57=1," "&真值表!J$1&"&",IF(真值表!J57=0,"~"&真值表!J$1&"&","")) | J57: =IF(真值表!K57=1," "&真值表!K$1&"&",IF(真值表!K57=0,"~"&真值表!K$1&"&","")) | K57: =IF(真值表!L57=1," "&真值表!L$1&"&",IF(真值表!L57=0,"~"&真值表!L$1&"&","")) | L57: =IF(真值表!M57=1," "&真值表!M$1&"&",IF(真值表!M57=0,"~"&真值表!M$1&"&","")) | ... N57: =IF(真值表!O57=1," "&真值表!O$1&"&",IF(真值表!O57=0,"~"&真值表!O$1&"&","")) | O57: =IF(LEN(CONCATENATE(E57,F57,G57,H57,I57,J57,K57,L57,M57,N57))=0,"",LEFT(CONCATENATE(E57,F57,G57,H57,I57,J57,K57,L57,M57,N57),LEN(CONCATENATE(E57,F57,G57,H57,I57,J57,K57,L57,M57,N57))-1)) | P57: =IF(真值表!Q57=1,$O57&"+","") | Q57: =IF(真值表!R57=1,$O57&"+","") | R57: =IF(真值表!S57=1,$O57&"+","") | S57: =IF(真值表!T57=1,$O57&"+","") | T57: =IF(真值表!U57=1,$O57&"+","") | U57: =IF(真值表!V57=1,$O57&"+","") | V57: =IF(真值表!W57=1,$O57&"+","") | W57: =IF(真值表!X57=1,$O57&"+","") | ... AL57: =IF(真值表!AM57=1,$O57&"+","")
A58: 逻辑表达式---> | P58: =IF(LEN(P59)>1,LEFT(P59,LEN(P59)-1),"") -> ~F30&~F25& F14& F13&~F12&~OP6& OP5& OP4&~OP3&~OP2+~F30&~F25&~F14& F13&~F12&~OP6& OP5& OP4&~OP3&~OP2+~F30&~F25&~F14& F13& F12&~OP6& OP5& OP4&~OP3&~OP2+ F14& F13&~F12&~OP6&~OP5& OP4&~OP3&~OP2+ F14&~F13&~F12&~OP6&~OP5& OP4&~OP3&~OP2+~F14& F13&~F12&~OP6&~OP5& OP4&~OP3&~OP2+ F14& F13&~F12& OP6& OP5& OP4&~OP3&~OP2+~F14& F13& F12&~OP6&~OP5& OP4&~OP3&~OP2+ F14&~F13&~F12& OP6& OP5&~OP4&~OP3&~OP2 | Q58: =IF(LEN(Q59)>1,LEFT(Q59,LEN(Q59)-1),"") -> ~F30&~F25&~F14&~F13&~F12&~OP6& OP5& OP4&~OP3&~OP2+ F30&~F25&~F14&~F13&~F12&~OP6& OP5& OP4&~OP3&~OP2+~F30&~F25& F14& F13& F12&~OP6& OP5& OP4&~OP3&~OP2+~F30&~F25&~F14& F13& F12&~OP6& OP5& OP4&~OP3&~OP2+~F14&~F13&~F12&~OP6&~OP5& OP4&~OP3&~OP2+ F14& F13& F12&~OP6&~OP5& OP4&~OP3&~OP2+~F14& F13&~F12&~OP6&~OP5&~OP4&~OP3&~OP2+~F14& F13&~F12&~OP6& OP5&~OP4&~OP3&~OP2+~F14&~F13&~F12& OP6& OP5&~OP4&~OP3&~OP2+~F14&~F13& F12& OP6& OP5&~OP4&~OP3&~OP2+~F14&~F13&~F12& OP6& OP5&~OP4&~OP3& OP2+ F14& F13& F12& OP6& OP5& OP4&~OP3&~OP2+~F14& F13& F12&~OP6&~OP5& OP4&~OP3&~OP2+ F14&~F13& F12&~OP6&~OP5&~OP4&~OP3&~OP2 | R58: =IF(LEN(R59)>1,LEFT(R59,LEN(R59)-1),"") -> F30&~F25&~F14&~F13&~F12&~OP6& OP5& OP4&~OP3&~OP2+~F30&~F25& F14& F13& F12&~OP6& OP5& OP4&~OP3&~OP2+~F30&~F25&~F14& F13&~F12&~OP6& OP5& OP4&~OP3&~OP2+ F14& F13& F12&~OP6&~OP5& OP4&~OP3&~OP2+~F14& F13&~F12&~OP6&~OP5& OP4&~OP3&~OP2+~F30&~F25& F14&~F13& F12&~OP6&~OP5& OP4&~OP3&~OP2+~F14&~F13&~F12& OP6& OP5&~OP4&~OP3&~OP2+~F14&~F13& F12& OP6& OP5&~OP4&~OP3&~OP2+~F14&~F13&~F12& OP6& OP5&~OP4&~OP3& OP2+ F14& F13& F12& OP6& OP5& OP4&~OP3&~OP2+ F14&~F13&~F12& OP6& OP5&~OP4&~OP3&~OP2 | S58: =IF(LEN(S59)>1,LEFT(S59,LEN(S59)-1),"") -> ~F30&~F25&~F14&~F13&~F12&~OP6& OP5& OP4&~OP3&~OP2+~F30&~F25& F14& F13& F12&~OP6& OP5& OP4&~OP3&~OP2+~F30&~F25&~F14& F13&~F12&~OP6& OP5& OP4&~OP3&~OP2+~F14&~F13&~F12&~OP6&~OP5& OP4&~OP3&~OP2+ F14& F13& F12&~OP6&~OP5& OP4&~OP3&~OP2+ F14&~F13&~F12&~OP6&~OP5& OP4&~OP3&~OP2+~F14& F13&~F12&~OP6&~OP5& OP4&~OP3&~OP2+ F30&~F25& F14&~F13& F12&~OP6&~OP5& OP4&~OP3&~OP2+~F14& F13&~F12&~OP6&~OP5&~OP4&~OP3&~OP2+~F14& F13&~F12&~OP6& OP5&~OP4&~OP3&~OP2+ F14& F13& F12& OP6& OP5& OP4&~OP3&~OP2+ F30&~F25& F14&~F13& F12&~OP6& OP5& OP4&~OP3&~OP2+ F14&~F13& F12&~OP6&~OP5&~OP4&~OP3&~OP2+ F14&~F13&~F12& OP6& OP5&~OP4&~OP3&~OP2 | T58: =IF(LEN(T59)>1,LEFT(T59,LEN(T59)-1),"") -> ~F14& F13&~F12&~OP6&~OP5&~OP4&~OP3&~OP2+ F14&~F13& F12&~OP6&~OP5&~OP4&~OP3&~OP2 | U58: =IF(LEN(U59)>1,LEFT(U59,LEN(U59)-1),"") -> ~F14& F13&~F12&~OP6& OP5&~OP4&~OP3&~OP2 | V58: =IF(LEN(V59)>1,LEFT(V59,LEN(V59)-1),"") -> ~F14&~F13&~F12&~OP6&~OP5& OP4&~OP3&~OP2+ F14& F13& F12&~OP6&~OP5& OP4&~OP3&~OP2+ F14& F13&~F12&~OP6&~OP5& OP4&~OP3&~OP2+ F14&~F13&~F12&~OP6&~OP5& OP4&~OP3&~OP2+~F14& F13&~F12&~OP6&~OP5& OP4&~OP3&~OP2+~F30&~F25&~F14&~F13& F12&~OP6&~OP5& OP4&~OP3&~OP2+~F30&~F25& F14&~F13& F12&~OP6&~OP5& OP4&~OP3&~OP2+ F30&~F25& F14&~F13& F12&~OP6&~OP5& OP4&~OP3&~OP2+~F14& F13&~F12&~OP6&~OP5&~OP4&~OP3&~OP2+~F14& F13&~F12&~OP6& OP5&~OP4&~OP3&~OP2+~F14&~F13&~F12& OP6& OP5&~OP4&~OP3& OP2+~F14& F13& F12&~OP6&~OP5& OP4&~OP3&~OP2+ F14&~F13& F12&~OP6&~OP5&~OP4&~OP3&~OP2 | W58: =IF(LEN(W59)>1,LEFT(W59,LEN(W59)-1),"") -> ~F30&~F25&~F14&~F13&~F12&~OP6& OP5& OP4&~OP3&~OP2+ F30&~F25&~F14&~F13&~F12&~OP6& OP5& OP4&~OP3&~OP2+~F30&~F25& F14& F13& F12&~OP6& OP5& OP4&~OP3&~OP2+~F30&~F25& F14& F13&~F12&~OP6& OP5& OP4&~OP3&~OP2+~F30&~F25&~F14& F13&~F12&~OP6& OP5& OP4&~OP3&~OP2+~F30&~F25&~F14& F13& F12&~OP6& OP5& OP4&~OP3&~OP2+~F14&~F13&~F12&~OP6&~OP5& OP4&~OP3&~OP2+ F14& F13& F12&~OP6&~OP5& OP4&~OP3&~OP2+ F14& F13&~F12&~OP6&~OP5& OP4&~OP3&~OP2+ F14&~F13&~F12&~OP6&~OP5& OP4&~OP3&~OP2+~F14& F13&~F12&~OP6&~OP5& OP4&~OP3&~OP2+~F30&~F25&~F14&~F13& F12&~OP6&~OP5& OP4&~OP3&~OP2+~F30&~F25& F14&~F13& F12&~OP6&~OP5& OP4&~OP3&~OP2+ F30&~F25& F14&~F13& F12&~OP6&~OP5& OP4&~OP3&~OP2+~F14& F13&~F12&~OP6&~OP5&~OP4&~OP3&~OP2+ OP6& OP5&~OP4& OP3& OP2+~F14&~F13&~F12& OP6& OP5&~OP4&~OP3& OP2+ F30&~F25& F14&~F13& F12&~OP6& OP5& OP4&~OP3&~OP2+~F14& F13& F12&~OP6&~OP5& OP4&~OP3&~OP2+ F14&~F13& F12&~OP6&~OP5&~OP4&~OP3&~OP2 | ... AL58: =IF(LEN(AL59)>1,LEFT(AL59,LEN(AL59)-1),"")
